Workbook

Sheet CPY TOC
B2: Monthly CPY Sheet
F3: CPY Calculation Period
B4: Month of CPY | C4: 44958 | F4: Start Date | G4: End Date | N4: 4.3 | O4: Template Version
B5: Prepared By | C5: xxxxxxx | F5: 44947 | G5: 44977 | N5: Sentheel | O5: Updated by
B6: BU Name | C6: xxxxxxx | N6: 43917 | O6: Updated date
B7: Domain Manager/DH | C7: xxxxxxx
C9: Review details | E9: Re-review details
B10: Version No.
B11: Date
B12: Reviewed by
B15: Payment on | C15: No. of Resources | D15: Amount
B16: Support Allowance | C16: =COUNTIFS(CPY!M:M,">0") -> 0 | D16: =SUM(CPY!M3:M500) -> 0
B17: Shift Allowance | C17: =COUNTIFS(CPY!R:R,">0") -> 0 | D17: =SUM(CPY!R3:R500) -> 0
B18: OOH | C18: =COUNTIFS(CPY!V:V,">0") -> 0 | D18: =SUM(CPY!V3:V500) -> 0
B19: On Call | C19: =COUNTIFS(CPY!Z:Z,">0") -> 0 | D19: =SUM(CPY!Z3:Z500) -> 0
B20: Call Out | C20: =COUNTIFS(CPY!AC:AC,">0") -> 0 | D20: =SUM(CPY!AC3:AC500) -> 0
B21: Cab Expense | C21: =COUNTIFS(CPY!AF:AF,">0") -> 0 | D21: =SUM(CPY!AF3:AF500) -> 0
B23: Total | D23: =SUM(D16:D22) -> 0

Sheet Summary
A1: Sl .No | B1: Emp ID | C1: Employee Name | D1: Level | F1: Total
A3: 1 | B3: 67 | C3: Srikar S S | D3: M1 | F3: =SUMIF(CPY!$B:$B,Summary!$B3,CPY!$I:$I) -> 0
A4: =+A3+1 -> 2 | B4: 91 | C4: Niranjana Devi G | D4: M2 | F4: =SUMIF(CPY!$B:$B,Summary!$B4,CPY!$I:$I) -> 0
A5: =+A4+1 -> 3 | B5: 101 | C5: Karthik T S | D5: M2 | F5: =SUMIF(CPY!$B:$B,Summary!$B5,CPY!$I:$I) -> 0
A6: =+A5+1 -> 4 | B6: 115 | C6: Sujay B N | D6: A1 | F6: =SUMIF(CPY!$B:$B,Summary!$B6,CPY!$I:$I) -> 0
A7: =+A6+1 -> 5 | B7: 120 | C7: Nagendra K N | D7: T1 | F7: =SUMIF(CPY!$B:$B,Summary!$B7,CPY!$I:$I) -> 0
A8: =+A7+1 -> 6 | B8: 130 | C8: Shuba Sridhar | D8: A1 | F8: =SUMIF(CPY!$B:$B,Summary!$B8,CPY!$I:$I) -> 0
A9: =+A8+1 -> 7 | B9: 213 | C9: Ranganath GM | D9: T1 | F9: =SUMIF(CPY!$B:$B,Summary!$B9,CPY!$I:$I) -> 0
A10: =+A9+1 -> 8 | B10: 243 | C10: Rashmi S Uttarkar | D10: M1 | F10: =SUMIF(CPY!$B:$B,Summary!$B10,CPY!$I:$I) -> 0
A11: =+A10+1 -> 9 | B11: 249 | C11: Ramananda Govindappa | D11: T1 | F11: =SUMIF(CPY!$B:$B,Summary!$B11,CPY!$I:$I) -> 0
A12: =+A11+1 -> 10 | B12: 260 | C12: Ommer Shamreez | D12: D4 | F12: =SUMIF(CPY!$B:$B,Summary!$B12,CPY!$I:$I) -> 0
A13: =+A12+1 -> 11 | B13: 324 | C13: Nasirul Haque | D13: D4 | F13: =SUMIF(CPY!$B:$B,Summary!$B13,CPY!$I:$I) -> 0
A14: =+A13+1 -> 12 | B14: 335 | C14: Uma Gangadharaiah | D14: M1 | F14: =SUMIF(CPY!$B:$B,Summary!$B14,CPY!$I:$I) -> 0
A15: =+A14+1 -> 13 | B15: 374 | C15: Ramappa Nashi | D15: M1 | F15: =SUMIF(CPY!$B:$B,Summary!$B15,CPY!$I:$I) -> 0
... A1989: =+A1988+1 -> 1987 | B1989: 7236 | C1989: Abdul Samadh | D1989: D2 | F1989: =SUMIF(CPY!$B:$B,Summary!$B1989,CPY!$I:$I) -> 0

Sheet CPY
A1: Sl .No | B1: Emp ID | C1: Employee Name | D1: Level | E1: Project Type | F1: Project Name | G1: Component IDs/Name | I1: Total | K1: Support Allowance - To be Filled in days | O1: Shift Allowance - To be Filled in days | T1: OOH - To be Filled in Hours | X1: On Call - To be Filled in days | AB1: Call out - To be Filled in Hours | AE1: Cab Expense - To be Filled in days
K2: No. of Support projec Working Days | L2: No. of Leaves/Comp Off/Holidays | M2: Amount | O2: 6:30 AM to 03:30 PM | P2: 1 - 9 PM / 2:30PM - 11:30 PM | Q2: 11 PM to 7:00 AM | R2: Amount | T2: On Non-workdays | U2: On workdays | V2: Amount | X2: Oncall on a Normal workdays 8+ hours | Y2: Oncall on Non- workdays | Z2: Amount | AB2: Call out hours | AC2: Amount | AE2: No of Days | AF2: Amount
A3: 1 | B3: 5713 | C3: =IF(ISNA(VLOOKUP($B3,Summary!$B:$D,2,FALSE))=TRUE," ",VLOOKUP($B3,Summary!$B:$D,2,FALSE)) | D3: =IF(ISNA(VLOOKUP($B3,Summary!$B:$D,3,FALSE))=TRUE," ",VLOOKUP($B3,Summary!$B:$D,3,FALSE)) | E3: Support(L1_L2) | F3: 3IE | G3: HG356IE2023678 | I3: =M3+R3+V3+Z3+AC3+AF3 -> 0 | K3: =IF(E3="Support(L1_L2)",IF(NOT(ISBLANK(B3)),IF(NOT(ISBLANK(D3)),NETWORKDAYS('CPY TOC'!$F$5,'CPY TOC'!$G$5))))-L3 -> 0 | L3: =IF(E3="Support(L1_L2)",SUMIFS(Support_allowance_Entries!$G:$G,Support_allowance_Entries!$B:$B,CPY!B3),0) -> 0 | M3: =IF($D3="D0",MD!$C$4*(K3),IF($D3="D1",MD!$C$5*(K3),IF($D3="D2",MD!$C$6*(K3),IF($D3="D3",MD!$C$7*(K3),IF($D3="D4",MD!$C$8*(K3),IF($D3="D5",MD!$C$9*(K3),IF($D3="M1",MD!$C$10*(K3),IF($D3="T1",MD!$C$11*(K3))))))))) -> FALSE | O3: =SUMIFS(Shift_allowance_Entries!$G:$G,Shift_allowance_Entries!$F:$F,"6:30AM-03:30PM",Shift_allowance_Entries!$B:$B,CPY!$B3) -> 0 | P3: =SUMIFS(Shift_allowance_Entries!$G:$G,Shift_allowance_Entries!$F:$F,"1-9PM/2:30PM-11:30PM",Shift_allowance_Entries!$B:$B,CPY!$B3) -> 0 | Q3: =SUMIFS(Shift_allowance_Entries!$G:$G,Shift_allowance_Entries!$F:$F,"11PM-7AM",Shift_allowance_Entries!$B:$B,CPY!$B3) -> 0 | R3: =(CPY!O3*MD!$F$4)+(CPY!P3*MD!$F$5)+(CPY!Q3*MD!$F$6) -> 0 | T3: =ROUNDUP((SUMIFS('OOH Activities'!$K:$K,'OOH Activities'!$F:$F,"Non_workdays",'OOH Activities'!$B:$B,CPY!B3)) *24,1) -> 0 | U3: =ROUNDUP((SUMIFS('OOH Activities'!$K:$K,'OOH Activities'!$F:$F,"Workdays",'OOH Activities'!$B:$B,CPY!B3)) *24,1) -> 0 | V3: =ROUNDUP((SUMIFS('OOH Activities'!$L:$L,'OOH Activities'!$B:$B,CPY!B3)),1) -> 0 | X3: =ROUNDUP((SUMIFS('ON Call_Call Out Activities'!$L:$L,'ON Call_Call Out Activities'!$F:$F,"Workdays",'ON Call_Call Out Activities'!$B:$B,CPY!B3))*24,1) -> 0 | Y3: =ROUNDUP((SUMIFS('ON Call_Call Out Activities'!$L:$L,'ON Call_Call Out Activities'!$F:$F,"Non_workdays",'ON Call_Call Out Activities'!$B:$B,CPY!B3)) *24,1) -> 0 | Z3: =ROUNDUP((SUMIFS('ON Call_Call Out Activities'!$M:$M,'ON Call_Call Out Activities'!$F:$F,"Non_workdays",'ON Call_Call Out Activities'!$B:$B,CPY!B3)),1) + ROUNDUP((SUMIFS('ON Call_Call Out Activities'!$M:$M,'ON Call_Call Out Activities'!$F:$F,"Workdays",'ON Call_Call Out Activities'!$B:$B,CPY!B3)),1) -> 0 | AB3: =ROUNDUP((SUMIFS('ON Call_Call Out Activities'!$L:$L,'ON Call_Call Out Activities'!$F:$F,"Call_Out",'ON Call_Call Out Activities'!$B:$B,CPY!B3)) *24,1) -> 0 | AC3: =ROUNDUP((SUMIFS('ON Call_Call Out Activities'!$M:$M,'ON Call_Call Out Activities'!$F:$F,"Call_Out",'ON Call_Call Out Activities'!$B:$B,CPY!B3)),1) -> 0 | AE3: =IF((SUMIF(Shift_allowance_Entries!$B:$B,CPY!$B3,Shift_allowance_Entries!$H:$H)) > (SUMIF(Shift_allowance_Entries!$B:$B,CPY!$B3,Shift_allowance_Entries!$G:$G)),0,((SUMIF(Shift_allowance_Entries!$B:$B,CPY!$B3,Shift_allowance_Entries!$G:$G))-(SUMIF(Shift_allowance_Entries!$B:$B,CPY!$B3,Shift_allowance_Entries!$H:$H)))) -> 0 | AF3: =AE3*MD!$S$4 -> 0
A4: 2 | B4: 5053 | C4: =IF(ISNA(VLOOKUP($B4,Summary!$B:$D,2,FALSE))=TRUE," ",VLOOKUP($B4,Summary!$B:$D,2,FALSE)) | D4: =IF(ISNA(VLOOKUP($B4,Summary!$B:$D,3,FALSE))=TRUE," ",VLOOKUP($B4,Summary!$B:$D,3,FALSE)) | E4: Support(L1_L2) | F4: 3IE | G4: HG356IE2023678 | I4: =M4+R4+V4+Z4+AC4+AF4 -> 0 | K4: =IF(E4="Support(L1_L2)",IF(NOT(ISBLANK(B4)),IF(NOT(ISBLANK(D4)),NETWORKDAYS('CPY TOC'!$F$5,'CPY TOC'!$G$5))))-L4 -> 0 | L4: =IF(E4="Support(L1_L2)",SUMIFS(Support_allowance_Entries!$G:$G,Support_allowance_Entries!$B:$B,CPY!B4),0) -> 0 | M4: =IF($D4="D0",MD!$C$4*(K4),IF($D4="D1",MD!$C$5*(K4),IF($D4="D2",MD!$C$6*(K4),IF($D4="D3",MD!$C$7*(K4),IF($D4="D4",MD!$C$8*(K4),IF($D4="D5",MD!$C$9*(K4),IF($D4="M1",MD!$C$10*(K4),IF($D4="T1",MD!$C$11*(K4))))))))) -> FALSE | O4: =SUMIFS(Shift_allowance_Entries!$G:$G,Shift_allowance_Entries!$F:$F,"6:30AM-03:30PM",Shift_allowance_Entries!$B:$B,CPY!$B4) -> 0 | P4: =SUMIFS(Shift_allowance_Entries!$G:$G,Shift_allowance_Entries!$F:$F,"1-9PM/2:30PM-11:30PM",Shift_allowance_Entries!$B:$B,CPY!$B4) -> 0 | Q4: =SUMIFS(Shift_allowance_Entries!$G:$G,Shift_allowance_Entries!$F:$F,"11PM-7AM",Shift_allowance_Entries!$B:$B,CPY!$B4) -> 0 | R4: =(CPY!O4*MD!$F$4)+(CPY!P4*MD!$F$5)+(CPY!Q4*MD!$F$6) -> 0 | T4: =ROUNDUP((SUMIFS('OOH Activities'!$K:$K,'OOH Activities'!$F:$F,"Non_workdays",'OOH Activities'!$B:$B,CPY!B4)) *24,1) -> 0 | U4: =ROUNDUP((SUMIFS('OOH Activities'!$K:$K,'OOH Activities'!$F:$F,"Workdays",'OOH Activities'!$B:$B,CPY!B4)) *24,1) -> 0 | V4: =ROUNDUP((SUMIFS('OOH Activities'!$L:$L,'OOH Activities'!$B:$B,CPY!B4)),1) -> 0 | X4: =ROUNDUP((SUMIFS('ON Call_Call Out Activities'!$L:$L,'ON Call_Call Out Activities'!$F:$F,"Workdays",'ON Call_Call Out Activities'!$B:$B,CPY!B4))*24,1) -> 0 | Y4: =ROUNDUP((SUMIFS('ON Call_Call Out Activities'!$L:$L,'ON Call_Call Out Activities'!$F:$F,"Non_workdays",'ON Call_Call Out Activities'!$B:$B,CPY!B4)) *24,1) -> 0 | Z4: =ROUNDUP((SUMIFS('ON Call_Call Out Activities'!$M:$M,'ON Call_Call Out Activities'!$F:$F,"Non_workdays",'ON Call_Call Out Activities'!$B:$B,CPY!B4)),1) + ROUNDUP((SUMIFS('ON Call_Call Out Activities'!$M:$M,'ON Call_Call Out Activities'!$F:$F,"Workdays",'ON Call_Call Out Activities'!$B:$B,CPY!B4)),1) -> 0 | AB4: =ROUNDUP((SUMIFS('ON Call_Call Out Activities'!$L:$L,'ON Call_Call Out Activities'!$F:$F,"Call_Out",'ON Call_Call Out Activities'!$B:$B,CPY!B4)) *24,1) -> 0 | AC4: =ROUNDUP((SUMIFS('ON Call_Call Out Activities'!$M:$M,'ON Call_Call Out Activities'!$F:$F,"Call_Out",'ON Call_Call Out Activities'!$B:$B,CPY!B4)),1) -> 0 | AE4: =IF((SUMIF(Shift_allowance_Entries!$B:$B,CPY!$B4,Shift_allowance_Entries!$H:$H)) > (SUMIF(Shift_allowance_Entries!$B:$B,CPY!$B4,Shift_allowance_Entries!$G:$G)),0,((SUMIF(Shift_allowance_Entries!$B:$B,CPY!$B4,Shift_allowance_Entries!$G:$G))-(SUMIF(Shift_allowance_Entries!$B:$B,CPY!$B4,Shift_allowance_Entries!$H:$H)))) -> 0 | AF4: =AE4*MD!$S$4 -> 0
A5: 3 | B5: 6015 | C5: =IF(ISNA(VLOOKUP($B5,Summary!$B:$D,2,FALSE))=TRUE," ",VLOOKUP($B5,Summary!$B:$D,2,FALSE)) | D5: =IF(ISNA(VLOOKUP($B5,Summary!$B:$D,3,FALSE))=TRUE," ",VLOOKUP($B5,Summary!$B:$D,3,FALSE)) | E5: Support(L1_L2) | F5: 3IE | G5: HG356IE2023678 | I5: =M5+R5+V5+Z5+AC5+AF5 -> 0 | K5: =IF(E5="Support(L1_L2)",IF(NOT(ISBLANK(B5)),IF(NOT(ISBLANK(D5)),NETWORKDAYS('CPY TOC'!$F$5,'CPY TOC'!$G$5))))-L5 -> 0 | L5: =IF(E5="Support(L1_L2)",SUMIFS(Support_allowance_Entries!$G:$G,Support_allowance_Entries!$B:$B,CPY!B5),0) -> 0 | M5: =IF($D5="D0",MD!$C$4*(K5),IF($D5="D1",MD!$C$5*(K5),IF($D5="D2",MD!$C$6*(K5),IF($D5="D3",MD!$C$7*(K5),IF($D5="D4",MD!$C$8*(K5),IF($D5="D5",MD!$C$9*(K5),IF($D5="M1",MD!$C$10*(K5),IF($D5="T1",MD!$C$11*(K5))))))))) -> FALSE | O5: =SUMIFS(Shift_allowance_Entries!$G:$G,Shift_allowance_Entries!$F:$F,"6:30AM-03:30PM",Shift_allowance_Entries!$B:$B,CPY!$B5) -> 0 | P5: =SUMIFS(Shift_allowance_Entries!$G:$G,Shift_allowance_Entries!$F:$F,"1-9PM/2:30PM-11:30PM",Shift_allowance_Entries!$B:$B,CPY!$B5) -> 0 | Q5: =SUMIFS(Shift_allowance_Entries!$G:$G,Shift_allowance_Entries!$F:$F,"11PM-7AM",Shift_allowance_Entries!$B:$B,CPY!$B5) -> 0 | R5: =(CPY!O5*MD!$F$4)+(CPY!P5*MD!$F$5)+(CPY!Q5*MD!$F$6) -> 0 | T5: =ROUNDUP((SUMIFS('OOH Activities'!$K:$K,'OOH Activities'!$F:$F,"Non_workdays",'OOH Activities'!$B:$B,CPY!B5)) *24,1) -> 0 | U5: =ROUNDUP((SUMIFS('OOH Activities'!$K:$K,'OOH Activities'!$F:$F,"Workdays",'OOH Activities'!$B:$B,CPY!B5)) *24,1) -> 0 | V5: =ROUNDUP((SUMIFS('OOH Activities'!$L:$L,'OOH Activities'!$B:$B,CPY!B5)),1) -> 0 | X5: =ROUNDUP((SUMIFS('ON Call_Call Out Activities'!$L:$L,'ON Call_Call Out Activities'!$F:$F,"Workdays",'ON Call_Call Out Activities'!$B:$B,CPY!B5))*24,1) -> 0 | Y5: =ROUNDUP((SUMIFS('ON Call_Call Out Activities'!$L:$L,'ON Call_Call Out Activities'!$F:$F,"Non_workdays",'ON Call_Call Out Activities'!$B:$B,CPY!B5)) *24,1) -> 0 | Z5: =ROUNDUP((SUMIFS('ON Call_Call Out Activities'!$M:$M,'ON Call_Call Out Activities'!$F:$F,"Non_workdays",'ON Call_Call Out Activities'!$B:$B,CPY!B5)),1) + ROUNDUP((SUMIFS('ON Call_Call Out Activities'!$M:$M,'ON Call_Call Out Activities'!$F:$F,"Workdays",'ON Call_Call Out Activities'!$B:$B,CPY!B5)),1) -> 0 | AB5: =ROUNDUP((SUMIFS('ON Call_Call Out Activities'!$L:$L,'ON Call_Call Out Activities'!$F:$F,"Call_Out",'ON Call_Call Out Activities'!$B:$B,CPY!B5)) *24,1) -> 0 | AC5: =ROUNDUP((SUMIFS('ON Call_Call Out Activities'!$M:$M,'ON Call_Call Out Activities'!$F:$F,"Call_Out",'ON Call_Call Out Activities'!$B:$B,CPY!B5)),1) -> 0 | AE5: =IF((SUMIF(Shift_allowance_Entries!$B:$B,CPY!$B5,Shift_allowance_Entries!$H:$H)) > (SUMIF(Shift_allowance_Entries!$B:$B,CPY!$B5,Shift_allowance_Entries!$G:$G)),0,((SUMIF(Shift_allowance_Entries!$B:$B,CPY!$B5,Shift_allowance_Entries!$G:$G))-(SUMIF(Shift_allowance_Entries!$B:$B,CPY!$B5,Shift_allowance_Entries!$H:$H)))) -> 0 | AF5: =AE5*MD!$S$4 -> 0
A6: 4 | C6: =IF(ISNA(VLOOKUP($B6,Summary!$B:$D,2,FALSE))=TRUE," ",VLOOKUP($B6,Summary!$B:$D,2,FALSE)) | D6: =IF(ISNA(VLOOKUP($B6,Summary!$B:$D,3,FALSE))=TRUE," ",VLOOKUP($B6,Summary!$B:$D,3,FALSE)) | I6: =M6+R6+V6+Z6+AC6+AF6 -> 0 | K6: =IF(E6="Support(L1_L2)",IF(NOT(ISBLANK(B6)),IF(NOT(ISBLANK(D6)),NETWORKDAYS('CPY TOC'!$F$5,'CPY TOC'!$G$5))))-L6 -> 0 | L6: =IF(E6="Support(L1_L2)",SUMIFS(Support_allowance_Entries!$G:$G,Support_allowance_Entries!$B:$B,CPY!B6),0) -> 0 | M6: =IF($D6="D0",MD!$C$4*(K6),IF($D6="D1",MD!$C$5*(K6),IF($D6="D2",MD!$C$6*(K6),IF($D6="D3",MD!$C$7*(K6),IF($D6="D4",MD!$C$8*(K6),IF($D6="D5",MD!$C$9*(K6),IF($D6="M1",MD!$C$10*(K6),IF($D6="T1",MD!$C$11*(K6))))))))) -> FALSE | O6: =SUMIFS(Shift_allowance_Entries!$G:$G,Shift_allowance_Entries!$F:$F,"6:30AM-03:30PM",Shift_allowance_Entries!$B:$B,CPY!$B6) -> 0 | P6: =SUMIFS(Shift_allowance_Entries!$G:$G,Shift_allowance_Entries!$F:$F,"1-9PM/2:30PM-11:30PM",Shift_allowance_Entries!$B:$B,CPY!$B6) -> 0 | Q6: =SUMIFS(Shift_allowance_Entries!$G:$G,Shift_allowance_Entries!$F:$F,"11PM-7AM",Shift_allowance_Entries!$B:$B,CPY!$B6) -> 0 | R6: =(CPY!O6*MD!$F$4)+(CPY!P6*MD!$F$5)+(CPY!Q6*MD!$F$6) -> 0 | T6: =ROUNDUP((SUMIFS('OOH Activities'!$K:$K,'OOH Activities'!$F:$F,"Non_workdays",'OOH Activities'!$B:$B,CPY!B6)) *24,1) -> 0 | U6: =ROUNDUP((SUMIFS('OOH Activities'!$K:$K,'OOH Activities'!$F:$F,"Workdays",'OOH Activities'!$B:$B,CPY!B6)) *24,1) -> 0 | V6: =ROUNDUP((SUMIFS('OOH Activities'!$L:$L,'OOH Activities'!$B:$B,CPY!B6)),1) -> 0 | X6: =ROUNDUP((SUMIFS('ON Call_Call Out Activities'!$L:$L,'ON Call_Call Out Activities'!$F:$F,"Workdays",'ON Call_Call Out Activities'!$B:$B,CPY!B6))*24,1) -> 0 | Y6: =ROUNDUP((SUMIFS('ON Call_Call Out Activities'!$L:$L,'ON Call_Call Out Activities'!$F:$F,"Non_workdays",'ON Call_Call Out Activities'!$B:$B,CPY!B6)) *24,1) -> 0 | Z6: =ROUNDUP((SUMIFS('ON Call_Call Out Activities'!$M:$M,'ON Call_Call Out Activities'!$F:$F,"Non_workdays",'ON Call_Call Out Activities'!$B:$B,CPY!B6)),1) + ROUNDUP((SUMIFS('ON Call_Call Out Activities'!$M:$M,'ON Call_Call Out Activities'!$F:$F,"Workdays",'ON Call_Call Out Activities'!$B:$B,CPY!B6)),1) -> 0 | AB6: =ROUNDUP((SUMIFS('ON Call_Call Out Activities'!$L:$L,'ON Call_Call Out Activities'!$F:$F,"Call_Out",'ON Call_Call Out Activities'!$B:$B,CPY!B6)) *24,1) -> 0 | AC6: =ROUNDUP((SUMIFS('ON Call_Call Out Activities'!$M:$M,'ON Call_Call Out Activities'!$F:$F,"Call_Out",'ON Call_Call Out Activities'!$B:$B,CPY!B6)),1) -> 0 | AE6: =IF((SUMIF(Shift_allowance_Entries!$B:$B,CPY!$B6,Shift_allowance_Entries!$H:$H)) > (SUMIF(Shift_allowance_Entries!$B:$B,CPY!$B6,Shift_allowance_Entries!$G:$G)),0,((SUMIF(Shift_allowance_Entries!$B:$B,CPY!$B6,Shift_allowance_Entries!$G:$G))-(SUMIF(Shift_allowance_Entries!$B:$B,CPY!$B6,Shift_allowance_Entries!$H:$H)))) -> 0 | AF6: =AE6*MD!$S$4 -> 0
A7: 5 | C7: =IF(ISNA(VLOOKUP($B7,Summary!$B:$D,2,FALSE))=TRUE," ",VLOOKUP($B7,Summary!$B:$D,2,FALSE)) | D7: =IF(ISNA(VLOOKUP($B7,Summary!$B:$D,3,FALSE))=TRUE," ",VLOOKUP($B7,Summary!$B:$D,3,FALSE)) | I7: =M7+R7+V7+Z7+AC7+AF7 -> 0 | K7: =IF(E7="Support(L1_L2)",IF(NOT(ISBLANK(B7)),IF(NOT(ISBLANK(D7)),NETWORKDAYS('CPY TOC'!$F$5,'CPY TOC'!$G$5))))-L7 -> 0 | L7: =IF(E7="Support(L1_L2)",SUMIFS(Support_allowance_Entries!$G:$G,Support_allowance_Entries!$B:$B,CPY!B7),0) -> 0 | M7: =IF($D7="D0",MD!$C$4*(K7),IF($D7="D1",MD!$C$5*(K7),IF($D7="D2",MD!$C$6*(K7),IF($D7="D3",MD!$C$7*(K7),IF($D7="D4",MD!$C$8*(K7),IF($D7="D5",MD!$C$9*(K7),IF($D7="M1",MD!$C$10*(K7),IF($D7="T1",MD!$C$11*(K7))))))))) -> FALSE | O7: =SUMIFS(Shift_allowance_Entries!$G:$G,Shift_allowance_Entries!$F:$F,"6:30AM-03:30PM",Shift_allowance_Entries!$B:$B,CPY!$B7) -> 0 | P7: =SUMIFS(Shift_allowance_Entries!$G:$G,Shift_allowance_Entries!$F:$F,"1-9PM/2:30PM-11:30PM",Shift_allowance_Entries!$B:$B,CPY!$B7) -> 0 | Q7: =SUMIFS(Shift_allowance_Entries!$G:$G,Shift_allowance_Entries!$F:$F,"11PM-7AM",Shift_allowance_Entries!$B:$B,CPY!$B7) -> 0 | R7: =(CPY!O7*MD!$F$4)+(CPY!P7*MD!$F$5)+(CPY!Q7*MD!$F$6) -> 0 | T7: =ROUNDUP((SUMIFS('OOH Activities'!$K:$K,'OOH Activities'!$F:$F,"Non_workdays",'OOH Activities'!$B:$B,CPY!B7)) *24,1) -> 0 | U7: =ROUNDUP((SUMIFS('OOH Activities'!$K:$K,'OOH Activities'!$F:$F,"Workdays",'OOH Activities'!$B:$B,CPY!B7)) *24,1) -> 0 | V7: =ROUNDUP((SUMIFS('OOH Activities'!$L:$L,'OOH Activities'!$B:$B,CPY!B7)),1) -> 0 | X7: =ROUNDUP((SUMIFS('ON Call_Call Out Activities'!$L:$L,'ON Call_Call Out Activities'!$F:$F,"Workdays",'ON Call_Call Out Activities'!$B:$B,CPY!B7))*24,1) -> 0 | Y7: =ROUNDUP((SUMIFS('ON Call_Call Out Activities'!$L:$L,'ON Call_Call Out Activities'!$F:$F,"Non_workdays",'ON Call_Call Out Activities'!$B:$B,CPY!B7)) *24,1) -> 0 | Z7: =ROUNDUP((SUMIFS('ON Call_Call Out Activities'!$M:$M,'ON Call_Call Out Activities'!$F:$F,"Non_workdays",'ON Call_Call Out Activities'!$B:$B,CPY!B7)),1) + ROUNDUP((SUMIFS('ON Call_Call Out Activities'!$M:$M,'ON Call_Call Out Activities'!$F:$F,"Workdays",'ON Call_Call Out Activities'!$B:$B,CPY!B7)),1) -> 0 | AB7: =ROUNDUP((SUMIFS('ON Call_Call Out Activities'!$L:$L,'ON Call_Call Out Activities'!$F:$F,"Call_Out",'ON Call_Call Out Activities'!$B:$B,CPY!B7)) *24,1) -> 0 | AC7: =ROUNDUP((SUMIFS('ON Call_Call Out Activities'!$M:$M,'ON Call_Call Out Activities'!$F:$F,"Call_Out",'ON Call_Call Out Activities'!$B:$B,CPY!B7)),1) -> 0 | AE7: =IF((SUMIF(Shift_allowance_Entries!$B:$B,CPY!$B7,Shift_allowance_Entries!$H:$H)) > (SUMIF(Shift_allowance_Entries!$B:$B,CPY!$B7,Shift_allowance_Entries!$G:$G)),0,((SUMIF(Shift_allowance_Entries!$B:$B,CPY!$B7,Shift_allowance_Entries!$G:$G))-(SUMIF(Shift_allowance_Entries!$B:$B,CPY!$B7,Shift_allowance_Entries!$H:$H)))) -> 0 | AF7: =AE7*MD!$S$4 -> 0
A8: 6 | C8: =IF(ISNA(VLOOKUP($B8,Summary!$B:$D,2,FALSE))=TRUE," ",VLOOKUP($B8,Summary!$B:$D,2,FALSE)) | D8: =IF(ISNA(VLOOKUP($B8,Summary!$B:$D,3,FALSE))=TRUE," ",VLOOKUP($B8,Summary!$B:$D,3,FALSE)) | I8: =M8+R8+V8+Z8+AC8+AF8 -> 0 | K8: =IF(E8="Support(L1_L2)",IF(NOT(ISBLANK(B8)),IF(NOT(ISBLANK(D8)),NETWORKDAYS('CPY TOC'!$F$5,'CPY TOC'!$G$5))))-L8 -> 0 | L8: =IF(E8="Support(L1_L2)",SUMIFS(Support_allowance_Entries!$G:$G,Support_allowance_Entries!$B:$B,CPY!B8),0) -> 0 | M8: =IF($D8="D0",MD!$C$4*(K8),IF($D8="D1",MD!$C$5*(K8),IF($D8="D2",MD!$C$6*(K8),IF($D8="D3",MD!$C$7*(K8),IF($D8="D4",MD!$C$8*(K8),IF($D8="D5",MD!$C$9*(K8),IF($D8="M1",MD!$C$10*(K8),IF($D8="T1",MD!$C$11*(K8))))))))) -> FALSE | O8: =SUMIFS(Shift_allowance_Entries!$G:$G,Shift_allowance_Entries!$F:$F,"6:30AM-03:30PM",Shift_allowance_Entries!$B:$B,CPY!$B8) -> 0 | P8: =SUMIFS(Shift_allowance_Entries!$G:$G,Shift_allowance_Entries!$F:$F,"1-9PM/2:30PM-11:30PM",Shift_allowance_Entries!$B:$B,CPY!$B8) -> 0 | Q8: =SUMIFS(Shift_allowance_Entries!$G:$G,Shift_allowance_Entries!$F:$F,"11PM-7AM",Shift_allowance_Entries!$B:$B,CPY!$B8) -> 0 | R8: =(CPY!O8*MD!$F$4)+(CPY!P8*MD!$F$5)+(CPY!Q8*MD!$F$6) -> 0 | T8: =ROUNDUP((SUMIFS('OOH Activities'!$K:$K,'OOH Activities'!$F:$F,"Non_workdays",'OOH Activities'!$B:$B,CPY!B8)) *24,1) -> 0 | U8: =ROUNDUP((SUMIFS('OOH Activities'!$K:$K,'OOH Activities'!$F:$F,"Workdays",'OOH Activities'!$B:$B,CPY!B8)) *24,1) -> 0 | V8: =ROUNDUP((SUMIFS('OOH Activities'!$L:$L,'OOH Activities'!$B:$B,CPY!B8)),1) -> 0 | X8: =ROUNDUP((SUMIFS('ON Call_Call Out Activities'!$L:$L,'ON Call_Call Out Activities'!$F:$F,"Workdays",'ON Call_Call Out Activities'!$B:$B,CPY!B8))*24,1) -> 0 | Y8: =ROUNDUP((SUMIFS('ON Call_Call Out Activities'!$L:$L,'ON Call_Call Out Activities'!$F:$F,"Non_workdays",'ON Call_Call Out Activities'!$B:$B,CPY!B8)) *24,1) -> 0 | Z8: =ROUNDUP((SUMIFS('ON Call_Call Out Activities'!$M:$M,'ON Call_Call Out Activities'!$F:$F,"Non_workdays",'ON Call_Call Out Activities'!$B:$B,CPY!B8)),1) + ROUNDUP((SUMIFS('ON Call_Call Out Activities'!$M:$M,'ON Call_Call Out Activities'!$F:$F,"Workdays",'ON Call_Call Out Activities'!$B:$B,CPY!B8)),1) -> 0 | AB8: =ROUNDUP((SUMIFS('ON Call_Call Out Activities'!$L:$L,'ON Call_Call Out Activities'!$F:$F,"Call_Out",'ON Call_Call Out Activities'!$B:$B,CPY!B8)) *24,1) -> 0 | AC8: =ROUNDUP((SUMIFS('ON Call_Call Out Activities'!$M:$M,'ON Call_Call Out Activities'!$F:$F,"Call_Out",'ON Call_Call Out Activities'!$B:$B,CPY!B8)),1) -> 0 | AE8: =IF((SUMIF(Shift_allowance_Entries!$B:$B,CPY!$B8,Shift_allowance_Entries!$H:$H)) > (SUMIF(Shift_allowance_Entries!$B:$B,CPY!$B8,Shift_allowance_Entries!$G:$G)),0,((SUMIF(Shift_allowance_Entries!$B:$B,CPY!$B8,Shift_allowance_Entries!$G:$G))-(SUMIF(Shift_allowance_Entries!$B:$B,CPY!$B8,Shift_allowance_Entries!$H:$H)))) -> 0 | AF8: =AE8*MD!$S$4 -> 0
A9: 7 | C9: =IF(ISNA(VLOOKUP($B9,Summary!$B:$D,2,FALSE))=TRUE," ",VLOOKUP($B9,Summary!$B:$D,2,FALSE)) | D9: =IF(ISNA(VLOOKUP($B9,Summary!$B:$D,3,FALSE))=TRUE," ",VLOOKUP($B9,Summary!$B:$D,3,FALSE)) | I9: =M9+R9+V9+Z9+AC9+AF9 -> 0 | K9: =IF(E9="Support(L1_L2)",IF(NOT(ISBLANK(B9)),IF(NOT(ISBLANK(D9)),NETWORKDAYS('CPY TOC'!$F$5,'CPY TOC'!$G$5))))-L9 -> 0 | L9: =IF(E9="Support(L1_L2)",SUMIFS(Support_allowance_Entries!$G:$G,Support_allowance_Entries!$B:$B,CPY!B9),0) -> 0 | M9: =IF($D9="D0",MD!$C$4*(K9),IF($D9="D1",MD!$C$5*(K9),IF($D9="D2",MD!$C$6*(K9),IF($D9="D3",MD!$C$7*(K9),IF($D9="D4",MD!$C$8*(K9),IF($D9="D5",MD!$C$9*(K9),IF($D9="M1",MD!$C$10*(K9),IF($D9="T1",MD!$C$11*(K9))))))))) -> FALSE | O9: =SUMIFS(Shift_allowance_Entries!$G:$G,Shift_allowance_Entries!$F:$F,"6:30AM-03:30PM",Shift_allowance_Entries!$B:$B,CPY!$B9) -> 0 | P9: =SUMIFS(Shift_allowance_Entries!$G:$G,Shift_allowance_Entries!$F:$F,"1-9PM/2:30PM-11:30PM",Shift_allowance_Entries!$B:$B,CPY!$B9) -> 0 | Q9: =SUMIFS(Shift_allowance_Entries!$G:$G,Shift_allowance_Entries!$F:$F,"11PM-7AM",Shift_allowance_Entries!$B:$B,CPY!$B9) -> 0 | R9: =(CPY!O9*MD!$F$4)+(CPY!P9*MD!$F$5)+(CPY!Q9*MD!$F$6) -> 0 | T9: =ROUNDUP((SUMIFS('OOH Activities'!$K:$K,'OOH Activities'!$F:$F,"Non_workdays",'OOH Activities'!$B:$B,CPY!B9)) *24,1) -> 0 | U9: =ROUNDUP((SUMIFS('OOH Activities'!$K:$K,'OOH Activities'!$F:$F,"Workdays",'OOH Activities'!$B:$B,CPY!B9)) *24,1) -> 0 | V9: =ROUNDUP((SUMIFS('OOH Activities'!$L:$L,'OOH Activities'!$B:$B,CPY!B9)),1) -> 0 | X9: =ROUNDUP((SUMIFS('ON Call_Call Out Activities'!$L:$L,'ON Call_Call Out Activities'!$F:$F,"Workdays",'ON Call_Call Out Activities'!$B:$B,CPY!B9))*24,1) -> 0 | Y9: =ROUNDUP((SUMIFS('ON Call_Call Out Activities'!$L:$L,'ON Call_Call Out Activities'!$F:$F,"Non_workdays",'ON Call_Call Out Activities'!$B:$B,CPY!B9)) *24,1) -> 0 | Z9: =ROUNDUP((SUMIFS('ON Call_Call Out Activities'!$M:$M,'ON Call_Call Out Activities'!$F:$F,"Non_workdays",'ON Call_Call Out Activities'!$B:$B,CPY!B9)),1) + ROUNDUP((SUMIFS('ON Call_Call Out Activities'!$M:$M,'ON Call_Call Out Activities'!$F:$F,"Workdays",'ON Call_Call Out Activities'!$B:$B,CPY!B9)),1) -> 0 | AB9: =ROUNDUP((SUMIFS('ON Call_Call Out Activities'!$L:$L,'ON Call_Call Out Activities'!$F:$F,"Call_Out",'ON Call_Call Out Activities'!$B:$B,CPY!B9)) *24,1) -> 0 | AC9: =ROUNDUP((SUMIFS('ON Call_Call Out Activities'!$M:$M,'ON Call_Call Out Activities'!$F:$F,"Call_Out",'ON Call_Call Out Activities'!$B:$B,CPY!B9)),1) -> 0 | AE9: =IF((SUMIF(Shift_allowance_Entries!$B:$B,CPY!$B9,Shift_allowance_Entries!$H:$H)) > (SUMIF(Shift_allowance_Entries!$B:$B,CPY!$B9,Shift_allowance_Entries!$G:$G)),0,((SUMIF(Shift_allowance_Entries!$B:$B,CPY!$B9,Shift_allowance_Entries!$G:$G))-(SUMIF(Shift_allowance_Entries!$B:$B,CPY!$B9,Shift_allowance_Entries!$H:$H)))) -> 0 | AF9: =AE9*MD!$S$4 -> 0
A10: 8 | C10: =IF(ISNA(VLOOKUP($B10,Summary!$B:$D,2,FALSE))=TRUE," ",VLOOKUP($B10,Summary!$B:$D,2,FALSE)) | D10: =IF(ISNA(VLOOKUP($B10,Summary!$B:$D,3,FALSE))=TRUE," ",VLOOKUP($B10,Summary!$B:$D,3,FALSE)) | I10: =M10+R10+V10+Z10+AC10+AF10 -> 0 | K10: =IF(E10="Support(L1_L2)",IF(NOT(ISBLANK(B10)),IF(NOT(ISBLANK(D10)),NETWORKDAYS('CPY TOC'!$F$5,'CPY TOC'!$G$5))))-L10 -> 0 | L10: =IF(E10="Support(L1_L2)",SUMIFS(Support_allowance_Entries!$G:$G,Support_allowance_Entries!$B:$B,CPY!B10),0) -> 0 | M10: =IF($D10="D0",MD!$C$4*(K10),IF($D10="D1",MD!$C$5*(K10),IF($D10="D2",MD!$C$6*(K10),IF($D10="D3",MD!$C$7*(K10),IF($D10="D4",MD!$C$8*(K10),IF($D10="D5",MD!$C$9*(K10),IF($D10="M1",MD!$C$10*(K10),IF($D10="T1",MD!$C$11*(K10))))))))) -> FALSE | O10: =SUMIFS(Shift_allowance_Entries!$G:$G,Shift_allowance_Entries!$F:$F,"6:30AM-03:30PM",Shift_allowance_Entries!$B:$B,CPY!$B10) -> 0 | P10: =SUMIFS(Shift_allowance_Entries!$G:$G,Shift_allowance_Entries!$F:$F,"1-9PM/2:30PM-11:30PM",Shift_allowance_Entries!$B:$B,CPY!$B10) -> 0 | Q10: =SUMIFS(Shift_allowance_Entries!$G:$G,Shift_allowance_Entries!$F:$F,"11PM-7AM",Shift_allowance_Entries!$B:$B,CPY!$B10) -> 0 | R10: =(CPY!O10*MD!$F$4)+(CPY!P10*MD!$F$5)+(CPY!Q10*MD!$F$6) -> 0 | T10: =ROUNDUP((SUMIFS('OOH Activities'!$K:$K,'OOH Activities'!$F:$F,"Non_workdays",'OOH Activities'!$B:$B,CPY!B10)) *24,1) -> 0 | U10: =ROUNDUP((SUMIFS('OOH Activities'!$K:$K,'OOH Activities'!$F:$F,"Workdays",'OOH Activities'!$B:$B,CPY!B10)) *24,1) -> 0 | V10: =ROUNDUP((SUMIFS('OOH Activities'!$L:$L,'OOH Activities'!$B:$B,CPY!B10)),1) -> 0 | X10: =ROUNDUP((SUMIFS('ON Call_Call Out Activities'!$L:$L,'ON Call_Call Out Activities'!$F:$F,"Workdays",'ON Call_Call Out Activities'!$B:$B,CPY!B10))*24,1) -> 0 | Y10: =ROUNDUP((SUMIFS('ON Call_Call Out Activities'!$L:$L,'ON Call_Call Out Activities'!$F:$F,"Non_workdays",'ON Call_Call Out Activities'!$B:$B,CPY!B10)) *24,1) -> 0 | Z10: =ROUNDUP((SUMIFS('ON Call_Call Out Activities'!$M:$M,'ON Call_Call Out Activities'!$F:$F,"Non_workdays",'ON Call_Call Out Activities'!$B:$B,CPY!B10)),1) + ROUNDUP((SUMIFS('ON Call_Call Out Activities'!$M:$M,'ON Call_Call Out Activities'!$F:$F,"Workdays",'ON Call_Call Out Activities'!$B:$B,CPY!B10)),1) -> 0 | AB10: =ROUNDUP((SUMIFS('ON Call_Call Out Activities'!$L:$L,'ON Call_Call Out Activities'!$F:$F,"Call_Out",'ON Call_Call Out Activities'!$B:$B,CPY!B10)) *24,1) -> 0 | AC10: =ROUNDUP((SUMIFS('ON Call_Call Out Activities'!$M:$M,'ON Call_Call Out Activities'!$F:$F,"Call_Out",'ON Call_Call Out Activities'!$B:$B,CPY!B10)),1) -> 0 | AE10: =IF((SUMIF(Shift_allowance_Entries!$B:$B,CPY!$B10,Shift_allowance_Entries!$H:$H)) > (SUMIF(Shift_allowance_Entries!$B:$B,CPY!$B10,Shift_allowance_Entries!$G:$G)),0,((SUMIF(Shift_allowance_Entries!$B:$B,CPY!$B10,Shift_allowance_Entries!$G:$G))-(SUMIF(Shift_allowance_Entries!$B:$B,CPY!$B10,Shift_allowance_Entries!$H:$H)))) -> 0 | AF10: =AE10*MD!$S$4 -> 0
A11: 9 | C11: =IF(ISNA(VLOOKUP($B11,Summary!$B:$D,2,FALSE))=TRUE," ",VLOOKUP($B11,Summary!$B:$D,2,FALSE)) | D11: =IF(ISNA(VLOOKUP($B11,Summary!$B:$D,3,FALSE))=TRUE," ",VLOOKUP($B11,Summary!$B:$D,3,FALSE)) | I11: =M11+R11+V11+Z11+AC11+AF11 -> 0 | K11: =IF(E11="Support(L1_L2)",IF(NOT(ISBLANK(B11)),IF(NOT(ISBLANK(D11)),NETWORKDAYS('CPY TOC'!$F$5,'CPY TOC'!$G$5))))-L11 -> 0 | L11: =IF(E11="Support(L1_L2)",SUMIFS(Support_allowance_Entries!$G:$G,Support_allowance_Entries!$B:$B,CPY!B11),0) -> 0 | M11: =IF($D11="D0",MD!$C$4*(K11),IF($D11="D1",MD!$C$5*(K11),IF($D11="D2",MD!$C$6*(K11),IF($D11="D3",MD!$C$7*(K11),IF($D11="D4",MD!$C$8*(K11),IF($D11="D5",MD!$C$9*(K11),IF($D11="M1",MD!$C$10*(K11),IF($D11="T1",MD!$C$11*(K11))))))))) -> FALSE | O11: =SUMIFS(Shift_allowance_Entries!$G:$G,Shift_allowance_Entries!$F:$F,"6:30AM-03:30PM",Shift_allowance_Entries!$B:$B,CPY!$B11) -> 0 | P11: =SUMIFS(Shift_allowance_Entries!$G:$G,Shift_allowance_Entries!$F:$F,"1-9PM/2:30PM-11:30PM",Shift_allowance_Entries!$B:$B,CPY!$B11) -> 0 | Q11: =SUMIFS(Shift_allowance_Entries!$G:$G,Shift_allowance_Entries!$F:$F,"11PM-7AM",Shift_allowance_Entries!$B:$B,CPY!$B11) -> 0 | R11: =(CPY!O11*MD!$F$4)+(CPY!P11*MD!$F$5)+(CPY!Q11*MD!$F$6) -> 0 | T11: =ROUNDUP((SUMIFS('OOH Activities'!$K:$K,'OOH Activities'!$F:$F,"Non_workdays",'OOH Activities'!$B:$B,CPY!B11)) *24,1) -> 0 | U11: =ROUNDUP((SUMIFS('OOH Activities'!$K:$K,'OOH Activities'!$F:$F,"Workdays",'OOH Activities'!$B:$B,CPY!B11)) *24,1) -> 0 | V11: =ROUNDUP((SUMIFS('OOH Activities'!$L:$L,'OOH Activities'!$B:$B,CPY!B11)),1) -> 0 | X11: =ROUNDUP((SUMIFS('ON Call_Call Out Activities'!$L:$L,'ON Call_Call Out Activities'!$F:$F,"Workdays",'ON Call_Call Out Activities'!$B:$B,CPY!B11))*24,1) -> 0 | Y11: =ROUNDUP((SUMIFS('ON Call_Call Out Activities'!$L:$L,'ON Call_Call Out Activities'!$F:$F,"Non_workdays",'ON Call_Call Out Activities'!$B:$B,CPY!B11)) *24,1) -> 0 | Z11: =ROUNDUP((SUMIFS('ON Call_Call Out Activities'!$M:$M,'ON Call_Call Out Activities'!$F:$F,"Non_workdays",'ON Call_Call Out Activities'!$B:$B,CPY!B11)),1) + ROUNDUP((SUMIFS('ON Call_Call Out Activities'!$M:$M,'ON Call_Call Out Activities'!$F:$F,"Workdays",'ON Call_Call Out Activities'!$B:$B,CPY!B11)),1) -> 0 | AB11: =ROUNDUP((SUMIFS('ON Call_Call Out Activities'!$L:$L,'ON Call_Call Out Activities'!$F:$F,"Call_Out",'ON Call_Call Out Activities'!$B:$B,CPY!B11)) *24,1) -> 0 | AC11: =ROUNDUP((SUMIFS('ON Call_Call Out Activities'!$M:$M,'ON Call_Call Out Activities'!$F:$F,"Call_Out",'ON Call_Call Out Activities'!$B:$B,CPY!B11)),1) -> 0 | AE11: =IF((SUMIF(Shift_allowance_Entries!$B:$B,CPY!$B11,Shift_allowance_Entries!$H:$H)) > (SUMIF(Shift_allowance_Entries!$B:$B,CPY!$B11,Shift_allowance_Entries!$G:$G)),0,((SUMIF(Shift_allowance_Entries!$B:$B,CPY!$B11,Shift_allowance_Entries!$G:$G))-(SUMIF(Shift_allowance_Entries!$B:$B,CPY!$B11,Shift_allowance_Entries!$H:$H)))) -> 0 | AF11: =AE11*MD!$S$4 -> 0
A12: 10 | C12: =IF(ISNA(VLOOKUP($B12,Summary!$B:$D,2,FALSE))=TRUE," ",VLOOKUP($B12,Summary!$B:$D,2,FALSE)) | D12: =IF(ISNA(VLOOKUP($B12,Summary!$B:$D,3,FALSE))=TRUE," ",VLOOKUP($B12,Summary!$B:$D,3,FALSE)) | I12: =M12+R12+V12+Z12+AC12+AF12 -> 0 | K12: =IF(E12="Support(L1_L2)",IF(NOT(ISBLANK(B12)),IF(NOT(ISBLANK(D12)),NETWORKDAYS('CPY TOC'!$F$5,'CPY TOC'!$G$5))))-L12 -> 0 | L12: =IF(E12="Support(L1_L2)",SUMIFS(Support_allowance_Entries!$G:$G,Support_allowance_Entries!$B:$B,CPY!B12),0) -> 0 | M12: =IF($D12="D0",MD!$C$4*(K12),IF($D12="D1",MD!$C$5*(K12),IF($D12="D2",MD!$C$6*(K12),IF($D12="D3",MD!$C$7*(K12),IF($D12="D4",MD!$C$8*(K12),IF($D12="D5",MD!$C$9*(K12),IF($D12="M1",MD!$C$10*(K12),IF($D12="T1",MD!$C$11*(K12))))))))) -> FALSE | O12: =SUMIFS(Shift_allowance_Entries!$G:$G,Shift_allowance_Entries!$F:$F,"6:30AM-03:30PM",Shift_allowance_Entries!$B:$B,CPY!$B12) -> 0 | P12: =SUMIFS(Shift_allowance_Entries!$G:$G,Shift_allowance_Entries!$F:$F,"1-9PM/2:30PM-11:30PM",Shift_allowance_Entries!$B:$B,CPY!$B12) -> 0 | Q12: =SUMIFS(Shift_allowance_Entries!$G:$G,Shift_allowance_Entries!$F:$F,"11PM-7AM",Shift_allowance_Entries!$B:$B,CPY!$B12) -> 0 | R12: =(CPY!O12*MD!$F$4)+(CPY!P12*MD!$F$5)+(CPY!Q12*MD!$F$6) -> 0 | T12: =ROUNDUP((SUMIFS('OOH Activities'!$K:$K,'OOH Activities'!$F:$F,"Non_workdays",'OOH Activities'!$B:$B,CPY!B12)) *24,1) -> 0 | U12: =ROUNDUP((SUMIFS('OOH Activities'!$K:$K,'OOH Activities'!$F:$F,"Workdays",'OOH Activities'!$B:$B,CPY!B12)) *24,1) -> 0 | V12: =ROUNDUP((SUMIFS('OOH Activities'!$L:$L,'OOH Activities'!$B:$B,CPY!B12)),1) -> 0 | X12: =ROUNDUP((SUMIFS('ON Call_Call Out Activities'!$L:$L,'ON Call_Call Out Activities'!$F:$F,"Workdays",'ON Call_Call Out Activities'!$B:$B,CPY!B12))*24,1) -> 0 | Y12: =ROUNDUP((SUMIFS('ON Call_Call Out Activities'!$L:$L,'ON Call_Call Out Activities'!$F:$F,"Non_workdays",'ON Call_Call Out Activities'!$B:$B,CPY!B12)) *24,1) -> 0 | Z12: =ROUNDUP((SUMIFS('ON Call_Call Out Activities'!$M:$M,'ON Call_Call Out Activities'!$F:$F,"Non_workdays",'ON Call_Call Out Activities'!$B:$B,CPY!B12)),1) + ROUNDUP((SUMIFS('ON Call_Call Out Activities'!$M:$M,'ON Call_Call Out Activities'!$F:$F,"Workdays",'ON Call_Call Out Activities'!$B:$B,CPY!B12)),1) -> 0 | AB12: =ROUNDUP((SUMIFS('ON Call_Call Out Activities'!$L:$L,'ON Call_Call Out Activities'!$F:$F,"Call_Out",'ON Call_Call Out Activities'!$B:$B,CPY!B12)) *24,1) -> 0 | AC12: =ROUNDUP((SUMIFS('ON Call_Call Out Activities'!$M:$M,'ON Call_Call Out Activities'!$F:$F,"Call_Out",'ON Call_Call Out Activities'!$B:$B,CPY!B12)),1) -> 0 | AE12: =IF((SUMIF(Shift_allowance_Entries!$B:$B,CPY!$B12,Shift_allowance_Entries!$H:$H)) > (SUMIF(Shift_allowance_Entries!$B:$B,CPY!$B12,Shift_allowance_Entries!$G:$G)),0,((SUMIF(Shift_allowance_Entries!$B:$B,CPY!$B12,Shift_allowance_Entries!$G:$G))-(SUMIF(Shift_allowance_Entries!$B:$B,CPY!$B12,Shift_allowance_Entries!$H:$H)))) -> 0 | AF12: =AE12*MD!$S$4 -> 0
A13: 11 | C13: =IF(ISNA(VLOOKUP($B13,Summary!$B:$D,2,FALSE))=TRUE," ",VLOOKUP($B13,Summary!$B:$D,2,FALSE)) | D13: =IF(ISNA(VLOOKUP($B13,Summary!$B:$D,3,FALSE))=TRUE," ",VLOOKUP($B13,Summary!$B:$D,3,FALSE)) | I13: =M13+R13+V13+Z13+AC13+AF13 -> 0 | K13: =IF(E13="Support(L1_L2)",IF(NOT(ISBLANK(B13)),IF(NOT(ISBLANK(D13)),NETWORKDAYS('CPY TOC'!$F$5,'CPY TOC'!$G$5))))-L13 -> 0 | L13: =IF(E13="Support(L1_L2)",SUMIFS(Support_allowance_Entries!$G:$G,Support_allowance_Entries!$B:$B,CPY!B13),0) -> 0 | M13: =IF($D13="D0",MD!$C$4*(K13),IF($D13="D1",MD!$C$5*(K13),IF($D13="D2",MD!$C$6*(K13),IF($D13="D3",MD!$C$7*(K13),IF($D13="D4",MD!$C$8*(K13),IF($D13="D5",MD!$C$9*(K13),IF($D13="M1",MD!$C$10*(K13),IF($D13="T1",MD!$C$11*(K13))))))))) -> FALSE | O13: =SUMIFS(Shift_allowance_Entries!$G:$G,Shift_allowance_Entries!$F:$F,"6:30AM-03:30PM",Shift_allowance_Entries!$B:$B,CPY!$B13) -> 0 | P13: =SUMIFS(Shift_allowance_Entries!$G:$G,Shift_allowance_Entries!$F:$F,"1-9PM/2:30PM-11:30PM",Shift_allowance_Entries!$B:$B,CPY!$B13) -> 0 | Q13: =SUMIFS(Shift_allowance_Entries!$G:$G,Shift_allowance_Entries!$F:$F,"11PM-7AM",Shift_allowance_Entries!$B:$B,CPY!$B13) -> 0 | R13: =(CPY!O13*MD!$F$4)+(CPY!P13*MD!$F$5)+(CPY!Q13*MD!$F$6) -> 0 | T13: =ROUNDUP((SUMIFS('OOH Activities'!$K:$K,'OOH Activities'!$F:$F,"Non_workdays",'OOH Activities'!$B:$B,CPY!B13)) *24,1) -> 0 | U13: =ROUNDUP((SUMIFS('OOH Activities'!$K:$K,'OOH Activities'!$F:$F,"Workdays",'OOH Activities'!$B:$B,CPY!B13)) *24,1) -> 0 | V13: =ROUNDUP((SUMIFS('OOH Activities'!$L:$L,'OOH Activities'!$B:$B,CPY!B13)),1) -> 0 | X13: =ROUNDUP((SUMIFS('ON Call_Call Out Activities'!$L:$L,'ON Call_Call Out Activities'!$F:$F,"Workdays",'ON Call_Call Out Activities'!$B:$B,CPY!B13))*24,1) -> 0 | Y13: =ROUNDUP((SUMIFS('ON Call_Call Out Activities'!$L:$L,'ON Call_Call Out Activities'!$F:$F,"Non_workdays",'ON Call_Call Out Activities'!$B:$B,CPY!B13)) *24,1) -> 0 | Z13: =ROUNDUP((SUMIFS('ON Call_Call Out Activities'!$M:$M,'ON Call_Call Out Activities'!$F:$F,"Non_workdays",'ON Call_Call Out Activities'!$B:$B,CPY!B13)),1) + ROUNDUP((SUMIFS('ON Call_Call Out Activities'!$M:$M,'ON Call_Call Out Activities'!$F:$F,"Workdays",'ON Call_Call Out Activities'!$B:$B,CPY!B13)),1) -> 0 | AB13: =ROUNDUP((SUMIFS('ON Call_Call Out Activities'!$L:$L,'ON Call_Call Out Activities'!$F:$F,"Call_Out",'ON Call_Call Out Activities'!$B:$B,CPY!B13)) *24,1) -> 0 | AC13: =ROUNDUP((SUMIFS('ON Call_Call Out Activities'!$M:$M,'ON Call_Call Out Activities'!$F:$F,"Call_Out",'ON Call_Call Out Activities'!$B:$B,CPY!B13)),1) -> 0 | AE13: =IF((SUMIF(Shift_allowance_Entries!$B:$B,CPY!$B13,Shift_allowance_Entries!$H:$H)) > (SUMIF(Shift_allowance_Entries!$B:$B,CPY!$B13,Shift_allowance_Entries!$G:$G)),0,((SUMIF(Shift_allowance_Entries!$B:$B,CPY!$B13,Shift_allowance_Entries!$G:$G))-(SUMIF(Shift_allowance_Entries!$B:$B,CPY!$B13,Shift_allowance_Entries!$H:$H)))) -> 0 | AF13: =AE13*MD!$S$4 -> 0
A14: 12 | C14: =IF(ISNA(VLOOKUP($B14,Summary!$B:$D,2,FALSE))=TRUE," ",VLOOKUP($B14,Summary!$B:$D,2,FALSE)) | D14: =IF(ISNA(VLOOKUP($B14,Summary!$B:$D,3,FALSE))=TRUE," ",VLOOKUP($B14,Summary!$B:$D,3,FALSE)) | I14: =M14+R14+V14+Z14+AC14+AF14 -> 0 | K14: =IF(E14="Support(L1_L2)",IF(NOT(ISBLANK(B14)),IF(NOT(ISBLANK(D14)),NETWORKDAYS('CPY TOC'!$F$5,'CPY TOC'!$G$5))))-L14 -> 0 | L14: =IF(E14="Support(L1_L2)",SUMIFS(Support_allowance_Entries!$G:$G,Support_allowance_Entries!$B:$B,CPY!B14),0) -> 0 | M14: =IF($D14="D0",MD!$C$4*(K14),IF($D14="D1",MD!$C$5*(K14),IF($D14="D2",MD!$C$6*(K14),IF($D14="D3",MD!$C$7*(K14),IF($D14="D4",MD!$C$8*(K14),IF($D14="D5",MD!$C$9*(K14),IF($D14="M1",MD!$C$10*(K14),IF($D14="T1",MD!$C$11*(K14))))))))) -> FALSE | O14: =SUMIFS(Shift_allowance_Entries!$G:$G,Shift_allowance_Entries!$F:$F,"6:30AM-03:30PM",Shift_allowance_Entries!$B:$B,CPY!$B14) -> 0 | P14: =SUMIFS(Shift_allowance_Entries!$G:$G,Shift_allowance_Entries!$F:$F,"1-9PM/2:30PM-11:30PM",Shift_allowance_Entries!$B:$B,CPY!$B14) -> 0 | Q14: =SUMIFS(Shift_allowance_Entries!$G:$G,Shift_allowance_Entries!$F:$F,"11PM-7AM",Shift_allowance_Entries!$B:$B,CPY!$B14) -> 0 | R14: =(CPY!O14*MD!$F$4)+(CPY!P14*MD!$F$5)+(CPY!Q14*MD!$F$6) -> 0 | T14: =ROUNDUP((SUMIFS('OOH Activities'!$K:$K,'OOH Activities'!$F:$F,"Non_workdays",'OOH Activities'!$B:$B,CPY!B14)) *24,1) -> 0 | U14: =ROUNDUP((SUMIFS('OOH Activities'!$K:$K,'OOH Activities'!$F:$F,"Workdays",'OOH Activities'!$B:$B,CPY!B14)) *24,1) -> 0 | V14: =ROUNDUP((SUMIFS('OOH Activities'!$L:$L,'OOH Activities'!$B:$B,CPY!B14)),1) -> 0 | X14: =ROUNDUP((SUMIFS('ON Call_Call Out Activities'!$L:$L,'ON Call_Call Out Activities'!$F:$F,"Workdays",'ON Call_Call Out Activities'!$B:$B,CPY!B14))*24,1) -> 0 | Y14: =ROUNDUP((SUMIFS('ON Call_Call Out Activities'!$L:$L,'ON Call_Call Out Activities'!$F:$F,"Non_workdays",'ON Call_Call Out Activities'!$B:$B,CPY!B14)) *24,1) -> 0 | Z14: =ROUNDUP((SUMIFS('ON Call_Call Out Activities'!$M:$M,'ON Call_Call Out Activities'!$F:$F,"Non_workdays",'ON Call_Call Out Activities'!$B:$B,CPY!B14)),1) + ROUNDUP((SUMIFS('ON Call_Call Out Activities'!$M:$M,'ON Call_Call Out Activities'!$F:$F,"Workdays",'ON Call_Call Out Activities'!$B:$B,CPY!B14)),1) -> 0 | AB14: =ROUNDUP((SUMIFS('ON Call_Call Out Activities'!$L:$L,'ON Call_Call Out Activities'!$F:$F,"Call_Out",'ON Call_Call Out Activities'!$B:$B,CPY!B14)) *24,1) -> 0 | AC14: =ROUNDUP((SUMIFS('ON Call_Call Out Activities'!$M:$M,'ON Call_Call Out Activities'!$F:$F,"Call_Out",'ON Call_Call Out Activities'!$B:$B,CPY!B14)),1) -> 0 | AE14: =IF((SUMIF(Shift_allowance_Entries!$B:$B,CPY!$B14,Shift_allowance_Entries!$H:$H)) > (SUMIF(Shift_allowance_Entries!$B:$B,CPY!$B14,Shift_allowance_Entries!$G:$G)),0,((SUMIF(Shift_allowance_Entries!$B:$B,CPY!$B14,Shift_allowance_Entries!$G:$G))-(SUMIF(Shift_allowance_Entries!$B:$B,CPY!$B14,Shift_allowance_Entries!$H:$H)))) -> 0 | AF14: =AE14*MD!$S$4 -> 0
A15: 13 | C15: =IF(ISNA(VLOOKUP($B15,Summary!$B:$D,2,FALSE))=TRUE," ",VLOOKUP($B15,Summary!$B:$D,2,FALSE)) | D15: =IF(ISNA(VLOOKUP($B15,Summary!$B:$D,3,FALSE))=TRUE," ",VLOOKUP($B15,Summary!$B:$D,3,FALSE)) | I15: =M15+R15+V15+Z15+AC15+AF15 -> 0 | K15: =IF(E15="Support(L1_L2)",IF(NOT(ISBLANK(B15)),IF(NOT(ISBLANK(D15)),NETWORKDAYS('CPY TOC'!$F$5,'CPY TOC'!$G$5))))-L15 -> 0 | L15: =IF(E15="Support(L1_L2)",SUMIFS(Support_allowance_Entries!$G:$G,Support_allowance_Entries!$B:$B,CPY!B15),0) -> 0 | M15: =IF($D15="D0",MD!$C$4*(K15),IF($D15="D1",MD!$C$5*(K15),IF($D15="D2",MD!$C$6*(K15),IF($D15="D3",MD!$C$7*(K15),IF($D15="D4",MD!$C$8*(K15),IF($D15="D5",MD!$C$9*(K15),IF($D15="M1",MD!$C$10*(K15),IF($D15="T1",MD!$C$11*(K15))))))))) -> FALSE | O15: =SUMIFS(Shift_allowance_Entries!$G:$G,Shift_allowance_Entries!$F:$F,"6:30AM-03:30PM",Shift_allowance_Entries!$B:$B,CPY!$B15) -> 0 | P15: =SUMIFS(Shift_allowance_Entries!$G:$G,Shift_allowance_Entries!$F:$F,"1-9PM/2:30PM-11:30PM",Shift_allowance_Entries!$B:$B,CPY!$B15) -> 0 | Q15: =SUMIFS(Shift_allowance_Entries!$G:$G,Shift_allowance_Entries!$F:$F,"11PM-7AM",Shift_allowance_Entries!$B:$B,CPY!$B15) -> 0 | R15: =(CPY!O15*MD!$F$4)+(CPY!P15*MD!$F$5)+(CPY!Q15*MD!$F$6) -> 0 | T15: =ROUNDUP((SUMIFS('OOH Activities'!$K:$K,'OOH Activities'!$F:$F,"Non_workdays",'OOH Activities'!$B:$B,CPY!B15)) *24,1) -> 0 | U15: =ROUNDUP((SUMIFS('OOH Activities'!$K:$K,'OOH Activities'!$F:$F,"Workdays",'OOH Activities'!$B:$B,CPY!B15)) *24,1) -> 0 | V15: =ROUNDUP((SUMIFS('OOH Activities'!$L:$L,'OOH Activities'!$B:$B,CPY!B15)),1) -> 0 | X15: =ROUNDUP((SUMIFS('ON Call_Call Out Activities'!$L:$L,'ON Call_Call Out Activities'!$F:$F,"Workdays",'ON Call_Call Out Activities'!$B:$B,CPY!B15))*24,1) -> 0 | Y15: =ROUNDUP((SUMIFS('ON Call_Call Out Activities'!$L:$L,'ON Call_Call Out Activities'!$F:$F,"Non_workdays",'ON Call_Call Out Activities'!$B:$B,CPY!B15)) *24,1) -> 0 | Z15: =ROUNDUP((SUMIFS('ON Call_Call Out Activities'!$M:$M,'ON Call_Call Out Activities'!$F:$F,"Non_workdays",'ON Call_Call Out Activities'!$B:$B,CPY!B15)),1) + ROUNDUP((SUMIFS('ON Call_Call Out Activities'!$M:$M,'ON Call_Call Out Activities'!$F:$F,"Workdays",'ON Call_Call Out Activities'!$B:$B,CPY!B15)),1) -> 0 | AB15: =ROUNDUP((SUMIFS('ON Call_Call Out Activities'!$L:$L,'ON Call_Call Out Activities'!$F:$F,"Call_Out",'ON Call_Call Out Activities'!$B:$B,CPY!B15)) *24,1) -> 0 | AC15: =ROUNDUP((SUMIFS('ON Call_Call Out Activities'!$M:$M,'ON Call_Call Out Activities'!$F:$F,"Call_Out",'ON Call_Call Out Activities'!$B:$B,CPY!B15)),1) -> 0 | AE15: =IF((SUMIF(Shift_allowance_Entries!$B:$B,CPY!$B15,Shift_allowance_Entries!$H:$H)) > (SUMIF(Shift_allowance_Entries!$B:$B,CPY!$B15,Shift_allowance_Entries!$G:$G)),0,((SUMIF(Shift_allowance_Entries!$B:$B,CPY!$B15,Shift_allowance_Entries!$G:$G))-(SUMIF(Shift_allowance_Entries!$B:$B,CPY!$B15,Shift_allowance_Entries!$H:$H)))) -> 0 | AF15: =AE15*MD!$S$4 -> 0
A16: 14 | C16: =IF(ISNA(VLOOKUP($B16,Summary!$B:$D,2,FALSE))=TRUE," ",VLOOKUP($B16,Summary!$B:$D,2,FALSE)) | D16: =IF(ISNA(VLOOKUP($B16,Summary!$B:$D,3,FALSE))=TRUE," ",VLOOKUP($B16,Summary!$B:$D,3,FALSE)) | I16: =M16+R16+V16+Z16+AC16+AF16 -> 0 | K16: =IF(E16="Support(L1_L2)",IF(NOT(ISBLANK(B16)),IF(NOT(ISBLANK(D16)),NETWORKDAYS('CPY TOC'!$F$5,'CPY TOC'!$G$5))))-L16 -> 0 | L16: =IF(E16="Support(L1_L2)",SUMIFS(Support_allowance_Entries!$G:$G,Support_allowance_Entries!$B:$B,CPY!B16),0) -> 0 | M16: =IF($D16="D0",MD!$C$4*(K16),IF($D16="D1",MD!$C$5*(K16),IF($D16="D2",MD!$C$6*(K16),IF($D16="D3",MD!$C$7*(K16),IF($D16="D4",MD!$C$8*(K16),IF($D16="D5",MD!$C$9*(K16),IF($D16="M1",MD!$C$10*(K16),IF($D16="T1",MD!$C$11*(K16))))))))) -> FALSE | O16: =SUMIFS(Shift_allowance_Entries!$G:$G,Shift_allowance_Entries!$F:$F,"6:30AM-03:30PM",Shift_allowance_Entries!$B:$B,CPY!$B16) -> 0 | P16: =SUMIFS(Shift_allowance_Entries!$G:$G,Shift_allowance_Entries!$F:$F,"1-9PM/2:30PM-11:30PM",Shift_allowance_Entries!$B:$B,CPY!$B16) -> 0 | Q16: =SUMIFS(Shift_allowance_Entries!$G:$G,Shift_allowance_Entries!$F:$F,"11PM-7AM",Shift_allowance_Entries!$B:$B,CPY!$B16) -> 0 | R16: =(CPY!O16*MD!$F$4)+(CPY!P16*MD!$F$5)+(CPY!Q16*MD!$F$6) -> 0 | T16: =ROUNDUP((SUMIFS('OOH Activities'!$K:$K,'OOH Activities'!$F:$F,"Non_workdays",'OOH Activities'!$B:$B,CPY!B16)) *24,1) -> 0 | U16: =ROUNDUP((SUMIFS('OOH Activities'!$K:$K,'OOH Activities'!$F:$F,"Workdays",'OOH Activities'!$B:$B,CPY!B16)) *24,1) -> 0 | V16: =ROUNDUP((SUMIFS('OOH Activities'!$L:$L,'OOH Activities'!$B:$B,CPY!B16)),1) -> 0 | X16: =ROUNDUP((SUMIFS('ON Call_Call Out Activities'!$L:$L,'ON Call_Call Out Activities'!$F:$F,"Workdays",'ON Call_Call Out Activities'!$B:$B,CPY!B16))*24,1) -> 0 | Y16: =ROUNDUP((SUMIFS('ON Call_Call Out Activities'!$L:$L,'ON Call_Call Out Activities'!$F:$F,"Non_workdays",'ON Call_Call Out Activities'!$B:$B,CPY!B16)) *24,1) -> 0 | Z16: =ROUNDUP((SUMIFS('ON Call_Call Out Activities'!$M:$M,'ON Call_Call Out Activities'!$F:$F,"Non_workdays",'ON Call_Call Out Activities'!$B:$B,CPY!B16)),1) + ROUNDUP((SUMIFS('ON Call_Call Out Activities'!$M:$M,'ON Call_Call Out Activities'!$F:$F,"Workdays",'ON Call_Call Out Activities'!$B:$B,CPY!B16)),1) -> 0 | AB16: =ROUNDUP((SUMIFS('ON Call_Call Out Activities'!$L:$L,'ON Call_Call Out Activities'!$F:$F,"Call_Out",'ON Call_Call Out Activities'!$B:$B,CPY!B16)) *24,1) -> 0 | AC16: =ROUNDUP((SUMIFS('ON Call_Call Out Activities'!$M:$M,'ON Call_Call Out Activities'!$F:$F,"Call_Out",'ON Call_Call Out Activities'!$B:$B,CPY!B16)),1) -> 0 | AE16: =IF((SUMIF(Shift_allowance_Entries!$B:$B,CPY!$B16,Shift_allowance_Entries!$H:$H)) > (SUMIF(Shift_allowance_Entries!$B:$B,CPY!$B16,Shift_allowance_Entries!$G:$G)),0,((SUMIF(Shift_allowance_Entries!$B:$B,CPY!$B16,Shift_allowance_Entries!$G:$G))-(SUMIF(Shift_allowance_Entries!$B:$B,CPY!$B16,Shift_allowance_Entries!$H:$H)))) -> 0 | AF16: =AE16*MD!$S$4 -> 0
A17: 15 | C17: =IF(ISNA(VLOOKUP($B17,Summary!$B:$D,2,FALSE))=TRUE," ",VLOOKUP($B17,Summary!$B:$D,2,FALSE)) | D17: =IF(ISNA(VLOOKUP($B17,Summary!$B:$D,3,FALSE))=TRUE," ",VLOOKUP($B17,Summary!$B:$D,3,FALSE)) | I17: =M17+R17+V17+Z17+AC17+AF17 -> 0 | K17: =IF(E17="Support(L1_L2)",IF(NOT(ISBLANK(B17)),IF(NOT(ISBLANK(D17)),NETWORKDAYS('CPY TOC'!$F$5,'CPY TOC'!$G$5))))-L17 -> 0 | L17: =IF(E17="Support(L1_L2)",SUMIFS(Support_allowance_Entries!$G:$G,Support_allowance_Entries!$B:$B,CPY!B17),0) -> 0 | M17: =IF($D17="D0",MD!$C$4*(K17),IF($D17="D1",MD!$C$5*(K17),IF($D17="D2",MD!$C$6*(K17),IF($D17="D3",MD!$C$7*(K17),IF($D17="D4",MD!$C$8*(K17),IF($D17="D5",MD!$C$9*(K17),IF($D17="M1",MD!$C$10*(K17),IF($D17="T1",MD!$C$11*(K17))))))))) -> FALSE | O17: =SUMIFS(Shift_allowance_Entries!$G:$G,Shift_allowance_Entries!$F:$F,"6:30AM-03:30PM",Shift_allowance_Entries!$B:$B,CPY!$B17) -> 0 | P17: =SUMIFS(Shift_allowance_Entries!$G:$G,Shift_allowance_Entries!$F:$F,"1-9PM/2:30PM-11:30PM",Shift_allowance_Entries!$B:$B,CPY!$B17) -> 0 | Q17: =SUMIFS(Shift_allowance_Entries!$G:$G,Shift_allowance_Entries!$F:$F,"11PM-7AM",Shift_allowance_Entries!$B:$B,CPY!$B17) -> 0 | R17: =(CPY!O17*MD!$F$4)+(CPY!P17*MD!$F$5)+(CPY!Q17*MD!$F$6) -> 0 | T17: =ROUNDUP((SUMIFS('OOH Activities'!$K:$K,'OOH Activities'!$F:$F,"Non_workdays",'OOH Activities'!$B:$B,CPY!B17)) *24,1) -> 0 | U17: =ROUNDUP((SUMIFS('OOH Activities'!$K:$K,'OOH Activities'!$F:$F,"Workdays",'OOH Activities'!$B:$B,CPY!B17)) *24,1) -> 0 | V17: =ROUNDUP((SUMIFS('OOH Activities'!$L:$L,'OOH Activities'!$B:$B,CPY!B17)),1) -> 0 | X17: =ROUNDUP((SUMIFS('ON Call_Call Out Activities'!$L:$L,'ON Call_Call Out Activities'!$F:$F,"Workdays",'ON Call_Call Out Activities'!$B:$B,CPY!B17))*24,1) -> 0 | Y17: =ROUNDUP((SUMIFS('ON Call_Call Out Activities'!$L:$L,'ON Call_Call Out Activities'!$F:$F,"Non_workdays",'ON Call_Call Out Activities'!$B:$B,CPY!B17)) *24,1) -> 0 | Z17: =ROUNDUP((SUMIFS('ON Call_Call Out Activities'!$M:$M,'ON Call_Call Out Activities'!$F:$F,"Non_workdays",'ON Call_Call Out Activities'!$B:$B,CPY!B17)),1) + ROUNDUP((SUMIFS('ON Call_Call Out Activities'!$M:$M,'ON Call_Call Out Activities'!$F:$F,"Workdays",'ON Call_Call Out Activities'!$B:$B,CPY!B17)),1) -> 0 | AB17: =ROUNDUP((SUMIFS('ON Call_Call Out Activities'!$L:$L,'ON Call_Call Out Activities'!$F:$F,"Call_Out",'ON Call_Call Out Activities'!$B:$B,CPY!B17)) *24,1) -> 0 | AC17: =ROUNDUP((SUMIFS('ON Call_Call Out Activities'!$M:$M,'ON Call_Call Out Activities'!$F:$F,"Call_Out",'ON Call_Call Out Activities'!$B:$B,CPY!B17)),1) -> 0 | AE17: =IF((SUMIF(Shift_allowance_Entries!$B:$B,CPY!$B17,Shift_allowance_Entries!$H:$H)) > (SUMIF(Shift_allowance_Entries!$B:$B,CPY!$B17,Shift_allowance_Entries!$G:$G)),0,((SUMIF(Shift_allowance_Entries!$B:$B,CPY!$B17,Shift_allowance_Entries!$G:$G))-(SUMIF(Shift_allowance_Entries!$B:$B,CPY!$B17,Shift_allowance_Entries!$H:$H)))) -> 0 | AF17: =AE17*MD!$S$4 -> 0
... A500: 498 | C500: =IF(ISNA(VLOOKUP($B500,Summary!$B:$D,2,FALSE))=TRUE," ",VLOOKUP($B500,Summary!$B:$D,2,FALSE)) | D500: =IF(ISNA(VLOOKUP($B500,Summary!$B:$D,3,FALSE))=TRUE," ",VLOOKUP($B500,Summary!$B:$D,3,FALSE)) | I500: =M500+R500+V500+Z500+AC500+AF500 -> 0 | K500: =IF(E500="Support(L1_L2)",IF(NOT(ISBLANK(B500)),IF(NOT(ISBLANK(D500)),NETWORKDAYS('CPY TOC'!$F$5,'CPY TOC'!$G$5))))-L500 -> 0 | L500: =IF(E500="Support(L1_L2)",SUMIFS(Support_allowance_Entries!$G:$G,Support_allowance_Entries!$B:$B,CPY!B500),0) -> 0 | M500: =IF($D500="D0",MD!$C$4*(K500),IF($D500="D1",MD!$C$5*(K500),IF($D500="D2",MD!$C$6*(K500),IF($D500="D3",MD!$C$7*(K500),IF($D500="D4",MD!$C$8*(K500),IF($D500="D5",MD!$C$9*(K500),IF($D500="M1",MD!$C$10*(K500),IF($D500="T1",MD!$C$11*(K500))))))))) -> FALSE | O500: =SUMIFS(Shift_allowance_Entries!$G:$G,Shift_allowance_Entries!$F:$F,"6:30AM-03:30PM",Shift_allowance_Entries!$B:$B,CPY!$B500) -> 0 | P500: =SUMIFS(Shift_allowance_Entries!$G:$G,Shift_allowance_Entries!$F:$F,"1-9PM/2:30PM-11:30PM",Shift_allowance_Entries!$B:$B,CPY!$B500) -> 0 | Q500: =SUMIFS(Shift_allowance_Entries!$G:$G,Shift_allowance_Entries!$F:$F,"11PM-7AM",Shift_allowance_Entries!$B:$B,CPY!$B500) -> 0 | R500: =(CPY!O500*MD!$F$4)+(CPY!P500*MD!$F$5)+(CPY!Q500*MD!$F$6) -> 0 | T500: =ROUNDUP((SUMIFS('OOH Activities'!$K:$K,'OOH Activities'!$F:$F,"Non_workdays",'OOH Activities'!$B:$B,CPY!B500)) *24,1) -> 0 | U500: =ROUNDUP((SUMIFS('OOH Activities'!$K:$K,'OOH Activities'!$F:$F,"Workdays",'OOH Activities'!$B:$B,CPY!B500)) *24,1) -> 0 | V500: =ROUNDUP((SUMIFS('OOH Activities'!$L:$L,'OOH Activities'!$B:$B,CPY!B500)),1) -> 0 | X500: =ROUNDUP((SUMIFS('ON Call_Call Out Activities'!$L:$L,'ON Call_Call Out Activities'!$F:$F,"Workdays",'ON Call_Call Out Activities'!$B:$B,CPY!B500))*24,1) -> 0 | Y500: =ROUNDUP((SUMIFS('ON Call_Call Out Activities'!$L:$L,'ON Call_Call Out Activities'!$F:$F,"Non_workdays",'ON Call_Call Out Activities'!$B:$B,CPY!B500)) *24,1) -> 0 | Z500: =ROUNDUP((SUMIFS('ON Call_Call Out Activities'!$M:$M,'ON Call_Call Out Activities'!$F:$F,"Non_workdays",'ON Call_Call Out Activities'!$B:$B,CPY!B500)),1) + ROUNDUP((SUMIFS('ON Call_Call Out Activities'!$M:$M,'ON Call_Call Out Activities'!$F:$F,"Workdays",'ON Call_Call Out Activities'!$B:$B,CPY!B500)),1) -> 0 | AB500: =ROUNDUP((SUMIFS('ON Call_Call Out Activities'!$L:$L,'ON Call_Call Out Activities'!$F:$F,"Call_Out",'ON Call_Call Out Activities'!$B:$B,CPY!B500)) *24,1) -> 0 | AC500: =ROUNDUP((SUMIFS('ON Call_Call Out Activities'!$M:$M,'ON Call_Call Out Activities'!$F:$F,"Call_Out",'ON Call_Call Out Activities'!$B:$B,CPY!B500)),1) -> 0 | AE500: =IF((SUMIF(Shift_allowance_Entries!$B:$B,CPY!$B500,Shift_allowance_Entries!$H:$H)) > (SUMIF(Shift_allowance_Entries!$B:$B,CPY!$B500,Shift_allowance_Entries!$G:$G)),0,((SUMIF(Shift_allowance_Entries!$B:$B,CPY!$B500,Shift_allowance_Entries!$G:$G))-(SUMIF(Shift_allowance_Entries!$B:$B,CPY!$B500,Shift_allowance_Entries!$H:$H)))) -> 0 | AF500: =AE500*MD!$S$4 -> 0

Sheet Support_allowance_Entries
A1: Sl .No | B1: Emp ID | C1: Employee Name | D1: Level | E1: Project Name | F1: Leave Type | G1: No. of days | H1: Metions the dates
A2: 1 | B2: 5713 | C2: =IF(ISNA(VLOOKUP($B2,CPY!$B:$G,2,FALSE))=TRUE," ",VLOOKUP($B2,CPY!$B:$G,2,FALSE)) | D2: =IF(ISNA(VLOOKUP($B2,CPY!$B:$G,3,FALSE))=TRUE," ",VLOOKUP($B2,CPY!$B:$G,3,FALSE)) | E2: =IF(ISNA(VLOOKUP($B2,CPY!$B:$G,4,FALSE))=TRUE," ",VLOOKUP($B2,CPY!$B:$G,4,FALSE)) | F2: Holiday | G2: 2 | H2: 2/20/2023 2/20/2023
A3: 2 | B3: 5713 | C3: =IF(ISNA(VLOOKUP($B3,CPY!$B:$G,2,FALSE))=TRUE," ",VLOOKUP($B3,CPY!$B:$G,2,FALSE)) | D3: =IF(ISNA(VLOOKUP($B3,CPY!$B:$G,3,FALSE))=TRUE," ",VLOOKUP($B3,CPY!$B:$G,3,FALSE)) | E3: =IF(ISNA(VLOOKUP($B3,CPY!$B:$G,4,FALSE))=TRUE," ",VLOOKUP($B3,CPY!$B:$G,4,FALSE)) | F3: Leave | G3: 0.5 | H3: 2/20/2023
A4: 3 | B4: 5713 | C4: =IF(ISNA(VLOOKUP($B4,CPY!$B:$G,2,FALSE))=TRUE," ",VLOOKUP($B4,CPY!$B:$G,2,FALSE)) | D4: =IF(ISNA(VLOOKUP($B4,CPY!$B:$G,3,FALSE))=TRUE," ",VLOOKUP($B4,CPY!$B:$G,3,FALSE)) | E4: =IF(ISNA(VLOOKUP($B4,CPY!$B:$G,4,FALSE))=TRUE," ",VLOOKUP($B4,CPY!$B:$G,4,FALSE)) | F4: Leave | G4: 1 | H4: 1/20/2023
A5: 4 | B5: 5053 | C5: =IF(ISNA(VLOOKUP($B5,CPY!$B:$G,2,FALSE))=TRUE," ",VLOOKUP($B5,CPY!$B:$G,2,FALSE)) | D5: =IF(ISNA(VLOOKUP($B5,CPY!$B:$G,3,FALSE))=TRUE," ",VLOOKUP($B5,CPY!$B:$G,3,FALSE)) | E5: =IF(ISNA(VLOOKUP($B5,CPY!$B:$G,4,FALSE))=TRUE," ",VLOOKUP($B5,CPY!$B:$G,4,FALSE)) | F5: Holiday | G5: 1
A6: 5 | B6: 5053 | C6: =IF(ISNA(VLOOKUP($B6,CPY!$B:$G,2,FALSE))=TRUE," ",VLOOKUP($B6,CPY!$B:$G,2,FALSE)) | D6: =IF(ISNA(VLOOKUP($B6,CPY!$B:$G,3,FALSE))=TRUE," ",VLOOKUP($B6,CPY!$B:$G,3,FALSE)) | E6: =IF(ISNA(VLOOKUP($B6,CPY!$B:$G,4,FALSE))=TRUE," ",VLOOKUP($B6,CPY!$B:$G,4,FALSE)) | F6: Leave | G6: 2 | H6: 2/11/2023 2/12/2023
A7: 6 | B7: 6015 | C7: =IF(ISNA(VLOOKUP($B7,CPY!$B:$G,2,FALSE))=TRUE," ",VLOOKUP($B7,CPY!$B:$G,2,FALSE)) | D7: =IF(ISNA(VLOOKUP($B7,CPY!$B:$G,3,FALSE))=TRUE," ",VLOOKUP($B7,CPY!$B:$G,3,FALSE)) | E7: =IF(ISNA(VLOOKUP($B7,CPY!$B:$G,4,FALSE))=TRUE," ",VLOOKUP($B7,CPY!$B:$G,4,FALSE)) | F7: Holiday | G7: 1 | H7: 1/30/2023
A8: 7 | B8: 6015 | C8: =IF(ISNA(VLOOKUP($B8,CPY!$B:$G,2,FALSE))=TRUE," ",VLOOKUP($B8,CPY!$B:$G,2,FALSE)) | D8: =IF(ISNA(VLOOKUP($B8,CPY!$B:$G,3,FALSE))=TRUE," ",VLOOKUP($B8,CPY!$B:$G,3,FALSE)) | E8: =IF(ISNA(VLOOKUP($B8,CPY!$B:$G,4,FALSE))=TRUE," ",VLOOKUP($B8,CPY!$B:$G,4,FALSE)) | F8: Leave | G8: 0.5 | H8: 2/13/2023
A9: 8 | C9: =IF(ISNA(VLOOKUP($B9,CPY!$B:$G,2,FALSE))=TRUE," ",VLOOKUP($B9,CPY!$B:$G,2,FALSE)) | D9: =IF(ISNA(VLOOKUP($B9,CPY!$B:$G,3,FALSE))=TRUE," ",VLOOKUP($B9,CPY!$B:$G,3,FALSE)) | E9: =IF(ISNA(VLOOKUP($B9,CPY!$B:$G,4,FALSE))=TRUE," ",VLOOKUP($B9,CPY!$B:$G,4,FALSE))
A10: 9 | C10: =IF(ISNA(VLOOKUP($B10,CPY!$B:$G,2,FALSE))=TRUE," ",VLOOKUP($B10,CPY!$B:$G,2,FALSE)) | D10: =IF(ISNA(VLOOKUP($B10,CPY!$B:$G,3,FALSE))=TRUE," ",VLOOKUP($B10,CPY!$B:$G,3,FALSE)) | E10: =IF(ISNA(VLOOKUP($B10,CPY!$B:$G,4,FALSE))=TRUE," ",VLOOKUP($B10,CPY!$B:$G,4,FALSE))
A11: 10 | C11: =IF(ISNA(VLOOKUP($B11,CPY!$B:$G,2,FALSE))=TRUE," ",VLOOKUP($B11,CPY!$B:$G,2,FALSE)) | D11: =IF(ISNA(VLOOKUP($B11,CPY!$B:$G,3,FALSE))=TRUE," ",VLOOKUP($B11,CPY!$B:$G,3,FALSE)) | E11: =IF(ISNA(VLOOKUP($B11,CPY!$B:$G,4,FALSE))=TRUE," ",VLOOKUP($B11,CPY!$B:$G,4,FALSE))
A12: 11 | C12: =IF(ISNA(VLOOKUP($B12,CPY!$B:$G,2,FALSE))=TRUE," ",VLOOKUP($B12,CPY!$B:$G,2,FALSE)) | D12: =IF(ISNA(VLOOKUP($B12,CPY!$B:$G,3,FALSE))=TRUE," ",VLOOKUP($B12,CPY!$B:$G,3,FALSE)) | E12: =IF(ISNA(VLOOKUP($B12,CPY!$B:$G,4,FALSE))=TRUE," ",VLOOKUP($B12,CPY!$B:$G,4,FALSE))
A13: 12 | C13: =IF(ISNA(VLOOKUP($B13,CPY!$B:$G,2,FALSE))=TRUE," ",VLOOKUP($B13,CPY!$B:$G,2,FALSE)) | D13: =IF(ISNA(VLOOKUP($B13,CPY!$B:$G,3,FALSE))=TRUE," ",VLOOKUP($B13,CPY!$B:$G,3,FALSE)) | E13: =IF(ISNA(VLOOKUP($B13,CPY!$B:$G,4,FALSE))=TRUE," ",VLOOKUP($B13,CPY!$B:$G,4,FALSE))
A14: 13 | C14: =IF(ISNA(VLOOKUP($B14,CPY!$B:$G,2,FALSE))=TRUE," ",VLOOKUP($B14,CPY!$B:$G,2,FALSE)) | D14: =IF(ISNA(VLOOKUP($B14,CPY!$B:$G,3,FALSE))=TRUE," ",VLOOKUP($B14,CPY!$B:$G,3,FALSE)) | E14: =IF(ISNA(VLOOKUP($B14,CPY!$B:$G,4,FALSE))=TRUE," ",VLOOKUP($B14,CPY!$B:$G,4,FALSE))
A15: 14 | C15: =IF(ISNA(VLOOKUP($B15,CPY!$B:$G,2,FALSE))=TRUE," ",VLOOKUP($B15,CPY!$B:$G,2,FALSE)) | D15: =IF(ISNA(VLOOKUP($B15,CPY!$B:$G,3,FALSE))=TRUE," ",VLOOKUP($B15,CPY!$B:$G,3,FALSE)) | E15: =IF(ISNA(VLOOKUP($B15,CPY!$B:$G,4,FALSE))=TRUE," ",VLOOKUP($B15,CPY!$B:$G,4,FALSE))
A16: 15 | C16: =IF(ISNA(VLOOKUP($B16,CPY!$B:$G,2,FALSE))=TRUE," ",VLOOKUP($B16,CPY!$B:$G,2,FALSE)) | D16: =IF(ISNA(VLOOKUP($B16,CPY!$B:$G,3,FALSE))=TRUE," ",VLOOKUP($B16,CPY!$B:$G,3,FALSE)) | E16: =IF(ISNA(VLOOKUP($B16,CPY!$B:$G,4,FALSE))=TRUE," ",VLOOKUP($B16,CPY!$B:$G,4,FALSE))
A17: 16 | C17: =IF(ISNA(VLOOKUP($B17,CPY!$B:$G,2,FALSE))=TRUE," ",VLOOKUP($B17,CPY!$B:$G,2,FALSE)) | D17: =IF(ISNA(VLOOKUP($B17,CPY!$B:$G,3,FALSE))=TRUE," ",VLOOKUP($B17,CPY!$B:$G,3,FALSE)) | E17: =IF(ISNA(VLOOKUP($B17,CPY!$B:$G,4,FALSE))=TRUE," ",VLOOKUP($B17,CPY!$B:$G,4,FALSE))
A18: 17 | C18: =IF(ISNA(VLOOKUP($B18,CPY!$B:$G,2,FALSE))=TRUE," ",VLOOKUP($B18,CPY!$B:$G,2,FALSE)) | D18: =IF(ISNA(VLOOKUP($B18,CPY!$B:$G,3,FALSE))=TRUE," ",VLOOKUP($B18,CPY!$B:$G,3,FALSE)) | E18: =IF(ISNA(VLOOKUP($B18,CPY!$B:$G,4,FALSE))=TRUE," ",VLOOKUP($B18,CPY!$B:$G,4,FALSE))
A19: 18 | C19: =IF(ISNA(VLOOKUP($B19,CPY!$B:$G,2,FALSE))=TRUE," ",VLOOKUP($B19,CPY!$B:$G,2,FALSE)) | D19: =IF(ISNA(VLOOKUP($B19,CPY!$B:$G,3,FALSE))=TRUE," ",VLOOKUP($B19,CPY!$B:$G,3,FALSE)) | E19: =IF(ISNA(VLOOKUP($B19,CPY!$B:$G,4,FALSE))=TRUE," ",VLOOKUP($B19,CPY!$B:$G,4,FALSE))
A20: 19 | C20: =IF(ISNA(VLOOKUP($B20,CPY!$B:$G,2,FALSE))=TRUE," ",VLOOKUP($B20,CPY!$B:$G,2,FALSE)) | D20: =IF(ISNA(VLOOKUP($B20,CPY!$B:$G,3,FALSE))=TRUE," ",VLOOKUP($B20,CPY!$B:$G,3,FALSE)) | E20: =IF(ISNA(VLOOKUP($B20,CPY!$B:$G,4,FALSE))=TRUE," ",VLOOKUP($B20,CPY!$B:$G,4,FALSE))
... A500: 499 | C500: =IF(ISNA(VLOOKUP($B500,CPY!$B:$G,2,FALSE))=TRUE," ",VLOOKUP($B500,CPY!$B:$G,2,FALSE)) | D500: =IF(ISNA(VLOOKUP($B500,CPY!$B:$G,3,FALSE))=TRUE," ",VLOOKUP($B500,CPY!$B:$G,3,FALSE)) | E500: =IF(ISNA(VLOOKUP($B500,CPY!$B:$G,4,FALSE))=TRUE," ",VLOOKUP($B500,CPY!$B:$G,4,FALSE))

Sheet Shift_allowance_Entries
A1: Sl .No | B1: Emp ID | C1: Employee Name | D1: Level | E1: Project Name | F1: Shift Slab | G1: No. of days | H1: Company Cab Availed days/ Work From Home | I1: Mention the Cab Availed dates
A2: 1 | B2: 5713 | C2: =IF(ISNA(VLOOKUP($B2,CPY!$B:$G,2,FALSE))=TRUE," ",VLOOKUP($B2,CPY!$B:$G,2,FALSE)) | D2: =IF(ISNA(VLOOKUP($B2,CPY!$B:$G,3,FALSE))=TRUE," ",VLOOKUP($B2,CPY!$B:$G,3,FALSE)) | E2: =IF(ISNA(VLOOKUP($B2,CPY!$B:$G,4,FALSE))=TRUE," ",VLOOKUP($B2,CPY!$B:$G,4,FALSE)) | F2: 6:30AM-03:30PM | G2: 12 | H2: 10
A3: 2 | B3: 5713 | C3: =IF(ISNA(VLOOKUP($B3,CPY!$B:$G,2,FALSE))=TRUE," ",VLOOKUP($B3,CPY!$B:$G,2,FALSE)) | D3: =IF(ISNA(VLOOKUP($B3,CPY!$B:$G,3,FALSE))=TRUE," ",VLOOKUP($B3,CPY!$B:$G,3,FALSE)) | E3: =IF(ISNA(VLOOKUP($B3,CPY!$B:$G,4,FALSE))=TRUE," ",VLOOKUP($B3,CPY!$B:$G,4,FALSE)) | F3: 1-9PM/2:30PM-11:30PM | G3: 10 | H3: 10
A4: 3 | B4: 5053 | C4: =IF(ISNA(VLOOKUP($B4,CPY!$B:$G,2,FALSE))=TRUE," ",VLOOKUP($B4,CPY!$B:$G,2,FALSE)) | D4: =IF(ISNA(VLOOKUP($B4,CPY!$B:$G,3,FALSE))=TRUE," ",VLOOKUP($B4,CPY!$B:$G,3,FALSE)) | E4: =IF(ISNA(VLOOKUP($B4,CPY!$B:$G,4,FALSE))=TRUE," ",VLOOKUP($B4,CPY!$B:$G,4,FALSE)) | F4: 6:30AM-03:30PM | G4: 13 | H4: 1 | I4: 2/14/2023
A5: 4 | B5: 5053 | C5: =IF(ISNA(VLOOKUP($B5,CPY!$B:$G,2,FALSE))=TRUE," ",VLOOKUP($B5,CPY!$B:$G,2,FALSE)) | D5: =IF(ISNA(VLOOKUP($B5,CPY!$B:$G,3,FALSE))=TRUE," ",VLOOKUP($B5,CPY!$B:$G,3,FALSE)) | E5: =IF(ISNA(VLOOKUP($B5,CPY!$B:$G,4,FALSE))=TRUE," ",VLOOKUP($B5,CPY!$B:$G,4,FALSE)) | F5: 1-9PM/2:30PM-11:30PM | G5: 4 | H5: 0
A6: 5 | C6: =IF(ISNA(VLOOKUP($B6,CPY!$B:$G,2,FALSE))=TRUE," ",VLOOKUP($B6,CPY!$B:$G,2,FALSE)) | D6: =IF(ISNA(VLOOKUP($B6,CPY!$B:$G,3,FALSE))=TRUE," ",VLOOKUP($B6,CPY!$B:$G,3,FALSE)) | E6: =IF(ISNA(VLOOKUP($B6,CPY!$B:$G,4,FALSE))=TRUE," ",VLOOKUP($B6,CPY!$B:$G,4,FALSE))
A7: 6 | C7: =IF(ISNA(VLOOKUP($B7,CPY!$B:$G,2,FALSE))=TRUE," ",VLOOKUP($B7,CPY!$B:$G,2,FALSE)) | D7: =IF(ISNA(VLOOKUP($B7,CPY!$B:$G,3,FALSE))=TRUE," ",VLOOKUP($B7,CPY!$B:$G,3,FALSE)) | E7: =IF(ISNA(VLOOKUP($B7,CPY!$B:$G,4,FALSE))=TRUE," ",VLOOKUP($B7,CPY!$B:$G,4,FALSE))
A8: 7 | C8: =IF(ISNA(VLOOKUP($B8,CPY!$B:$G,2,FALSE))=TRUE," ",VLOOKUP($B8,CPY!$B:$G,2,FALSE)) | D8: =IF(ISNA(VLOOKUP($B8,CPY!$B:$G,3,FALSE))=TRUE," ",VLOOKUP($B8,CPY!$B:$G,3,FALSE)) | E8: =IF(ISNA(VLOOKUP($B8,CPY!$B:$G,4,FALSE))=TRUE," ",VLOOKUP($B8,CPY!$B:$G,4,FALSE))
A9: 8 | C9: =IF(ISNA(VLOOKUP($B9,CPY!$B:$G,2,FALSE))=TRUE," ",VLOOKUP($B9,CPY!$B:$G,2,FALSE)) | D9: =IF(ISNA(VLOOKUP($B9,CPY!$B:$G,3,FALSE))=TRUE," ",VLOOKUP($B9,CPY!$B:$G,3,FALSE)) | E9: =IF(ISNA(VLOOKUP($B9,CPY!$B:$G,4,FALSE))=TRUE," ",VLOOKUP($B9,CPY!$B:$G,4,FALSE))
A10: 9 | C10: =IF(ISNA(VLOOKUP($B10,CPY!$B:$G,2,FALSE))=TRUE," ",VLOOKUP($B10,CPY!$B:$G,2,FALSE)) | D10: =IF(ISNA(VLOOKUP($B10,CPY!$B:$G,3,FALSE))=TRUE," ",VLOOKUP($B10,CPY!$B:$G,3,FALSE)) | E10: =IF(ISNA(VLOOKUP($B10,CPY!$B:$G,4,FALSE))=TRUE," ",VLOOKUP($B10,CPY!$B:$G,4,FALSE))
A11: 10 | C11: =IF(ISNA(VLOOKUP($B11,CPY!$B:$G,2,FALSE))=TRUE," ",VLOOKUP($B11,CPY!$B:$G,2,FALSE)) | D11: =IF(ISNA(VLOOKUP($B11,CPY!$B:$G,3,FALSE))=TRUE," ",VLOOKUP($B11,CPY!$B:$G,3,FALSE)) | E11: =IF(ISNA(VLOOKUP($B11,CPY!$B:$G,4,FALSE))=TRUE," ",VLOOKUP($B11,CPY!$B:$G,4,FALSE))
A12: 11 | C12: =IF(ISNA(VLOOKUP($B12,CPY!$B:$G,2,FALSE))=TRUE," ",VLOOKUP($B12,CPY!$B:$G,2,FALSE)) | D12: =IF(ISNA(VLOOKUP($B12,CPY!$B:$G,3,FALSE))=TRUE," ",VLOOKUP($B12,CPY!$B:$G,3,FALSE)) | E12: =IF(ISNA(VLOOKUP($B12,CPY!$B:$G,4,FALSE))=TRUE," ",VLOOKUP($B12,CPY!$B:$G,4,FALSE))
A13: 12 | C13: =IF(ISNA(VLOOKUP($B13,CPY!$B:$G,2,FALSE))=TRUE," ",VLOOKUP($B13,CPY!$B:$G,2,FALSE)) | D13: =IF(ISNA(VLOOKUP($B13,CPY!$B:$G,3,FALSE))=TRUE," ",VLOOKUP($B13,CPY!$B:$G,3,FALSE)) | E13: =IF(ISNA(VLOOKUP($B13,CPY!$B:$G,4,FALSE))=TRUE," ",VLOOKUP($B13,CPY!$B:$G,4,FALSE))
A14: 13 | C14: =IF(ISNA(VLOOKUP($B14,CPY!$B:$G,2,FALSE))=TRUE," ",VLOOKUP($B14,CPY!$B:$G,2,FALSE)) | D14: =IF(ISNA(VLOOKUP($B14,CPY!$B:$G,3,FALSE))=TRUE," ",VLOOKUP($B14,CPY!$B:$G,3,FALSE)) | E14: =IF(ISNA(VLOOKUP($B14,CPY!$B:$G,4,FALSE))=TRUE," ",VLOOKUP($B14,CPY!$B:$G,4,FALSE))
A15: 14 | C15: =IF(ISNA(VLOOKUP($B15,CPY!$B:$G,2,FALSE))=TRUE," ",VLOOKUP($B15,CPY!$B:$G,2,FALSE)) | D15: =IF(ISNA(VLOOKUP($B15,CPY!$B:$G,3,FALSE))=TRUE," ",VLOOKUP($B15,CPY!$B:$G,3,FALSE)) | E15: =IF(ISNA(VLOOKUP($B15,CPY!$B:$G,4,FALSE))=TRUE," ",VLOOKUP($B15,CPY!$B:$G,4,FALSE))
